program=ml.DeveloperApiExample
SPARKLORD_MODE=CONFIG_INJECTION
cpu_cores=2
cpu_util=200
memory=4g
config_file_name=spark-defaults.conf
config_key=spark.memory.offHeap.size
config_value=80g

2025-03-26 04:11:11,532 INFO [main] org.apache.hadoop.yarn.server.resourcemanager.ResourceManager: STARTUP_MSG: 
/************************************************************
STARTUP_MSG: Starting ResourceManager
STARTUP_MSG:   host = master/172.20.1.10
STARTUP_MSG:   args = []
STARTUP_MSG:   version = 3.3.4
STARTUP_MSG:   build = https://github.com/apache/hadoop.git -r a585a73c3e02ac62350c136643a5e7f6095a3dbb; compiled by 'stevel' on 2022-07-29T12:32Z
STARTUP_MSG:   java = 1.8.0_432
************************************************************/
2025-03-26 04:11:11,537 INFO [main] org.apache.hadoop.yarn.server.resourcemanager.ResourceManager: registered UNIX signal handlers for [TERM, HUP, INT]
2025-03-26 04:11:11,797 INFO [main] org.apache.hadoop.yarn.server.resourcemanager.RMNMInfo: Registered RMInfo MBean
2025-03-26 04:11:11,801 INFO [main] org.apache.hadoop.conf.Configuration: found resource core-site.xml at file:/hadoop/etc/hadoop/core-site.xml
2025-03-26 04:11:11,836 INFO [main] org.apache.hadoop.conf.Configuration: resource-types.xml not found
2025-03-26 04:11:11,836 INFO [main] org.apache.hadoop.yarn.util.resource.ResourceUtils: Unable to find 'resource-types.xml'.
2025-03-26 04:11:11,859 INFO [main] org.apache.hadoop.conf.Configuration: found resource yarn-site.xml at file:/hadoop/etc/hadoop/yarn-site.xml
2025-03-26 04:11:11,864 INFO [main] org.apache.hadoop.yarn.metrics.GenericEventTypeMetrics: Registering GenericEventTypeMetrics
2025-03-26 04:11:11,865 INFO [main] org.apache.hadoop.yarn.event.AsyncDispatcher: Registering class org.apache.hadoop.yarn.server.resourcemanager.RMFatalEventType for class org.apache.hadoop.yarn.server.resourcemanager.ResourceManager$RMFatalEventDispatcher
2025-03-26 04:11:11,886 INFO [main] org.apache.hadoop.yarn.server.resourcemanager.security.NMTokenSecretManagerInRM: NMTokenKeyRollingInterval: 86400000ms and NMTokenKeyActivationDelay: 900000ms
2025-03-26 04:11:11,890 INFO [main] org.apache.hadoop.yarn.server.resourcemanager.security.RMContainerTokenSecretManager: ContainerTokenKeyRollingInterval: 86400000ms and ContainerTokenKeyActivationDelay: 900000ms
2025-03-26 04:11:11,906 INFO [main] org.apache.hadoop.yarn.server.resourcemanager.security.AMRMTokenSecretManager: AMRMTokenKeyRollingInterval: 86400000ms and AMRMTokenKeyActivationDelay: 900000 ms
2025-03-26 04:11:11,928 INFO [main] org.apache.hadoop.yarn.event.AsyncDispatcher: Registering class org.apache.hadoop.yarn.server.resourcemanager.recovery.RMStateStoreEventType for class org.apache.hadoop.yarn.server.resourcemanager.recovery.RMStateStore$ForwardingEventHandler
2025-03-26 04:11:11,930 INFO [main] org.apache.hadoop.yarn.event.AsyncDispatcher: Registering class org.apache.hadoop.yarn.server.resourcemanager.NodesListManagerEventType for class org.apache.hadoop.yarn.server.resourcemanager.NodesListManager
2025-03-26 04:11:11,930 INFO [main] org.apache.hadoop.yarn.server.resourcemanager.ResourceManager: Using Scheduler: org.apache.hadoop.yarn.server.resourcemanager.scheduler.capacity.CapacityScheduler
2025-03-26 04:11:11,950 INFO [main] org.apache.hadoop.yarn.event.AsyncDispatcher: Registering class org.apache.hadoop.yarn.server.resourcemanager.scheduler.event.SchedulerEventType for class org.apache.hadoop.yarn.server.resourcemanager.ResourceManager$SchedulerEventDispatcher
2025-03-26 04:11:11,951 INFO [main] org.apache.hadoop.yarn.event.AsyncDispatcher: Registering class org.apache.hadoop.yarn.server.resourcemanager.rmapp.RMAppEventType for class org.apache.hadoop.yarn.server.resourcemanager.ResourceManager$ApplicationEventDispatcher
2025-03-26 04:11:11,951 INFO [main] org.apache.hadoop.yarn.event.AsyncDispatcher: Registering class org.apache.hadoop.yarn.server.resourcemanager.rmapp.attempt.RMAppAttemptEventType for class org.apache.hadoop.yarn.server.resourcemanager.ResourceManager$ApplicationAttemptEventDispatcher
2025-03-26 04:11:11,951 INFO [main] org.apache.hadoop.yarn.event.AsyncDispatcher: Registering class org.apache.hadoop.yarn.server.resourcemanager.rmnode.RMNodeEventType for class org.apache.hadoop.yarn.server.resourcemanager.ResourceManager$NodeEventDispatcher
2025-03-26 04:11:11,980 INFO [main] org.apache.hadoop.metrics2.impl.MetricsConfig: Loaded properties from hadoop-metrics2.properties
2025-03-26 04:11:11,987 INFO [main] org.apache.hadoop.metrics2.impl.MetricsSystemImpl: Scheduled Metric snapshot period at 10 second(s).
2025-03-26 04:11:11,987 INFO [main] org.apache.hadoop.metrics2.impl.MetricsSystemImpl: ResourceManager metrics system started
2025-03-26 04:11:12,009 INFO [main] org.apache.hadoop.yarn.security.YarnAuthorizationProvider: org.apache.hadoop.yarn.security.ConfiguredYarnAuthorizer is instantiated.
2025-03-26 04:11:12,011 INFO [main] org.apache.hadoop.yarn.event.AsyncDispatcher: Registering class org.apache.hadoop.yarn.server.resourcemanager.RMAppManagerEventType for class org.apache.hadoop.yarn.server.resourcemanager.RMAppManager
2025-03-26 04:11:12,015 INFO [main] org.apache.hadoop.yarn.event.AsyncDispatcher: Registering class org.apache.hadoop.yarn.server.resourcemanager.amlauncher.AMLauncherEventType for class org.apache.hadoop.yarn.server.resourcemanager.amlauncher.ApplicationMasterLauncher
2025-03-26 04:11:12,265 INFO [main] org.apache.hadoop.yarn.server.resourcemanager.RMNMInfo: Registered RMNMInfo MBean
2025-03-26 04:11:12,265 INFO [main] org.apache.hadoop.yarn.server.resourcemanager.rmapp.monitor.RMAppLifetimeMonitor: Application lifelime monitor interval set to 3000 ms.
2025-03-26 04:11:12,268 INFO [main] org.apache.hadoop.yarn.server.resourcemanager.scheduler.placement.MultiNodeSortingManager: Initializing NodeSortingService=MultiNodeSortingManager
2025-03-26 04:11:12,270 INFO [main] org.apache.hadoop.util.HostsFileReader: Refreshing hosts (include/exclude) list
2025-03-26 04:11:12,270 INFO [main] org.apache.hadoop.util.HostsFileReader: Adding a node "172.20.1.11" to the list of included hosts from /hadoop/etc/hadoop/workers
2025-03-26 04:11:12,270 INFO [main] org.apache.hadoop.util.HostsFileReader: Adding a node "172.20.1.12" to the list of included hosts from /hadoop/etc/hadoop/workers
2025-03-26 04:11:12,270 INFO [main] org.apache.hadoop.util.HostsFileReader: Adding a node "172.20.1.13" to the list of included hosts from /hadoop/etc/hadoop/workers
2025-03-26 04:11:12,273 INFO [main] org.apache.hadoop.conf.Configuration: found resource capacity-scheduler.xml at file:/hadoop/etc/hadoop/capacity-scheduler.xml
2025-03-26 04:11:12,277 INFO [main] org.apache.hadoop.yarn.server.resourcemanager.scheduler.AbstractYarnScheduler: Minimum allocation = <memory:1024, vCores:1>
2025-03-26 04:11:12,277 INFO [main] org.apache.hadoop.yarn.server.resourcemanager.scheduler.AbstractYarnScheduler: Maximum allocation = <memory:8192, vCores:4>
2025-03-26 04:11:12,309 INFO [main] org.apache.hadoop.yarn.server.resourcemanager.scheduler.capacity.ParentQueue: root, capacity=1.0, absoluteCapacity=1.0, maxCapacity=1.0, absoluteMaxCapacity=1.0, state=RUNNING, acls=ADMINISTER_QUEUE:*SUBMIT_APP:*, labels=*,
, reservationsContinueLooking=true, orderingPolicy=utilization, priority=0
2025-03-26 04:11:12,309 INFO [main] org.apache.hadoop.yarn.server.resourcemanager.scheduler.capacity.ParentQueue: Initialized parent-queue root name=root, fullname=root
2025-03-26 04:11:12,325 INFO [main] org.apache.hadoop.yarn.server.resourcemanager.scheduler.capacity.LeafQueue: Initializing root.default
capacity = 1.0 [= (float) configuredCapacity / 100 ]
absoluteCapacity = 1.0 [= parentAbsoluteCapacity * capacity ]
maxCapacity = 1.0 [= configuredMaxCapacity ]
absoluteMaxCapacity = 1.0 [= 1.0 maximumCapacity undefined, (parentAbsoluteMaxCapacity * maximumCapacity) / 100 otherwise ]
effectiveMinResource=<memory:0, vCores:0>
 , effectiveMaxResource=<memory:0, vCores:0>
userLimit = 100 [= configuredUserLimit ]
userLimitFactor = 1.0 [= configuredUserLimitFactor ]
maxApplications = 10000 [= configuredMaximumSystemApplicationsPerQueue or (int)(configuredMaximumSystemApplications * absoluteCapacity)]
maxApplicationsPerUser = 10000 [= (int)(maxApplications * (userLimit / 100.0f) * userLimitFactor) ]
maxParallelApps = 2147483647
usedCapacity = 0.0 [= usedResourcesMemory / (clusterResourceMemory * absoluteCapacity)]
absoluteUsedCapacity = 0.0 [= usedResourcesMemory / clusterResourceMemory]
maxAMResourcePerQueuePercent = 0.1 [= configuredMaximumAMResourcePercent ]
minimumAllocationFactor = 0.875 [= (float)(maximumAllocationMemory - minimumAllocationMemory) / maximumAllocationMemory ]
maximumAllocation = <memory:8192, vCores:4> [= configuredMaxAllocation ]
numContainers = 0 [= currentNumContainers ]
state = RUNNING [= configuredState ]
acls = ADMINISTER_QUEUE:*SUBMIT_APP:* [= configuredAcls ]
nodeLocalityDelay = 40
rackLocalityAdditionalDelay = -1
labels=*,
reservationsContinueLooking = true
preemptionDisabled = true
defaultAppPriorityPerQueue = 0
priority = 0
maxLifetime = -1 seconds
defaultLifetime = -1 seconds
2025-03-26 04:11:12,327 INFO [main] org.apache.hadoop.yarn.server.resourcemanager.scheduler.capacity.CapacitySchedulerQueueManager: Initialized queue: root.default
2025-03-26 04:11:12,327 INFO [main] org.apache.hadoop.yarn.server.resourcemanager.scheduler.capacity.CapacitySchedulerQueueManager: Initialized queue: root
2025-03-26 04:11:12,329 INFO [main] org.apache.hadoop.yarn.server.resourcemanager.scheduler.capacity.CapacitySchedulerQueueManager: Initialized root queue root: numChildQueue= 1, capacity=1.0, absoluteCapacity=1.0, usedResources=<memory:0, vCores:0>usedCapacity=0.0, numApps=0, numContainers=0
2025-03-26 04:11:12,329 INFO [main] org.apache.hadoop.yarn.server.resourcemanager.placement.UserGroupMappingPlacementRule: Initialized queue mappings, override: false
2025-03-26 04:11:12,329 INFO [main] org.apache.hadoop.yarn.server.resourcemanager.scheduler.capacity.WorkflowPriorityMappingsManager: Initialized workflow priority mappings, override: false
2025-03-26 04:11:12,339 INFO [main] org.apache.hadoop.yarn.server.resourcemanager.scheduler.placement.MultiNodeSortingManager: MultiNode scheduling is 'false', and configured policies are 
2025-03-26 04:11:12,339 INFO [main] org.apache.hadoop.yarn.server.resourcemanager.scheduler.capacity.CapacityScheduler: Initialized CapacityScheduler with calculator=class org.apache.hadoop.yarn.util.resource.DefaultResourceCalculator, minimumAllocation=<<memory:1024, vCores:1>>, maximumAllocation=<<memory:8192, vCores:4>>, asynchronousScheduling=false, asyncScheduleInterval=5ms,multiNodePlacementEnabled=false, assignMultipleEnabled=true, maxAssignPerHeartbeat=100, offswitchPerHeartbeatLimit=1
2025-03-26 04:11:12,342 INFO [main] org.apache.hadoop.conf.Configuration: dynamic-resources.xml not found
2025-03-26 04:11:12,345 INFO [main] org.apache.hadoop.yarn.server.resourcemanager.AMSProcessingChain: Initializing AMS Processing chain. Root Processor=[org.apache.hadoop.yarn.server.resourcemanager.DefaultAMSProcessor].
2025-03-26 04:11:12,345 INFO [main] org.apache.hadoop.yarn.server.resourcemanager.ApplicationMasterService: disabled placement handler will be used, all scheduling requests will be rejected.
2025-03-26 04:11:12,346 INFO [main] org.apache.hadoop.yarn.server.resourcemanager.AMSProcessingChain: Adding [org.apache.hadoop.yarn.server.resourcemanager.scheduler.constraint.processor.DisabledPlacementProcessor] tp top of AMS Processing chain. 
2025-03-26 04:11:12,349 INFO [main] org.apache.hadoop.yarn.server.resourcemanager.ResourceManager: TimelineServicePublisher is not configured
2025-03-26 04:11:12,368 INFO [main] org.eclipse.jetty.util.log: Logging initialized @1093ms to org.eclipse.jetty.util.log.Slf4jLog
2025-03-26 04:11:12,453 WARN [main] org.apache.hadoop.security.authentication.server.AuthenticationFilter: Unable to initialize FileSignerSecretProvider, falling back to use random secrets. Reason: Could not read signature secret file: /root/hadoop-http-auth-signature-secret
2025-03-26 04:11:12,457 INFO [main] org.apache.hadoop.http.HttpRequestLog: Http request log for http.requests.resourcemanager is not defined
2025-03-26 04:11:12,461 INFO [main] org.apache.hadoop.http.HttpServer2: Added global filter 'safety' (class=org.apache.hadoop.http.HttpServer2$QuotingInputFilter)
2025-03-26 04:11:12,463 INFO [main] org.apache.hadoop.http.HttpServer2: Added filter RMAuthenticationFilter (class=org.apache.hadoop.yarn.server.security.http.RMAuthenticationFilter) to context cluster
2025-03-26 04:11:12,463 INFO [main] org.apache.hadoop.http.HttpServer2: Added filter RMAuthenticationFilter (class=org.apache.hadoop.yarn.server.security.http.RMAuthenticationFilter) to context logs
2025-03-26 04:11:12,463 INFO [main] org.apache.hadoop.http.HttpServer2: Added filter RMAuthenticationFilter (class=org.apache.hadoop.yarn.server.security.http.RMAuthenticationFilter) to context static
2025-03-26 04:11:12,464 INFO [main] org.apache.hadoop.http.HttpServer2: Added filter static_user_filter (class=org.apache.hadoop.http.lib.StaticUserWebFilter$StaticUserFilter) to context cluster
2025-03-26 04:11:12,464 INFO [main] org.apache.hadoop.http.HttpServer2: Added filter static_user_filter (class=org.apache.hadoop.http.lib.StaticUserWebFilter$StaticUserFilter) to context logs
2025-03-26 04:11:12,464 INFO [main] org.apache.hadoop.http.HttpServer2: Added filter static_user_filter (class=org.apache.hadoop.http.lib.StaticUserWebFilter$StaticUserFilter) to context static
2025-03-26 04:11:12,684 INFO [main] org.apache.hadoop.yarn.webapp.WebApps: Registered webapp guice modules
2025-03-26 04:11:12,687 INFO [main] org.apache.hadoop.http.HttpServer2: Jetty bound to port 8088
2025-03-26 04:11:12,688 INFO [main] org.eclipse.jetty.server.Server: jetty-9.4.43.v20210629; built: 2021-06-30T11:07:22.254Z; git: 526006ecfa3af7f1a27ef3a288e2bef7ea9dd7e8; jvm 1.8.0_432-8u432-ga~us1-0ubuntu2~24.04-ga
2025-03-26 04:11:12,716 INFO [main] org.eclipse.jetty.server.session: DefaultSessionIdManager workerName=node0
2025-03-26 04:11:12,716 INFO [main] org.eclipse.jetty.server.session: No SessionScavenger set, using defaults
2025-03-26 04:11:12,717 INFO [main] org.eclipse.jetty.server.session: node0 Scavenging every 660000ms
2025-03-26 04:11:12,728 WARN [main] org.apache.hadoop.security.authentication.server.AuthenticationFilter: Unable to initialize FileSignerSecretProvider, falling back to use random secrets. Reason: Could not read signature secret file: /root/hadoop-http-auth-signature-secret
2025-03-26 04:11:12,733 INFO [main] org.apache.hadoop.security.token.delegation.AbstractDelegationTokenSecretManager: Updating the current master key for generating delegation tokens
2025-03-26 04:11:12,740 INFO [Thread[Thread-20,5,main]] org.apache.hadoop.security.token.delegation.AbstractDelegationTokenSecretManager: Starting expired delegation token remover thread, tokenRemoverScanInterval=60 min(s)
2025-03-26 04:11:12,740 INFO [Thread[Thread-20,5,main]] org.apache.hadoop.security.token.delegation.AbstractDelegationTokenSecretManager: Updating the current master key for generating delegation tokens
2025-03-26 04:11:12,745 INFO [main] org.eclipse.jetty.server.handler.ContextHandler: Started o.e.j.s.ServletContextHandler@305a0c5f{logs,/logs,file:///hadoop/logs/,AVAILABLE}
2025-03-26 04:11:12,746 INFO [main] org.eclipse.jetty.server.handler.ContextHandler: Started o.e.j.s.ServletContextHandler@232a7d73{static,/static,jar:file:/hadoop/share/hadoop/yarn/hadoop-yarn-common-3.3.4.jar!/webapps/static,AVAILABLE}
2025-03-26 04:11:13,260 INFO [main] org.eclipse.jetty.server.handler.ContextHandler: Started o.e.j.w.WebAppContext@7add323c{cluster,/,file:///tmp/jetty-master-8088-hadoop-yarn-common-3_3_4_jar-_-any-5969992812745126614/webapp/,AVAILABLE}{jar:file:/hadoop/share/hadoop/yarn/hadoop-yarn-common-3.3.4.jar!/webapps/cluster}
2025-03-26 04:11:13,265 INFO [main] org.eclipse.jetty.server.AbstractConnector: Started ServerConnector@5b068087{HTTP/1.1, (http/1.1)}{master:8088}
2025-03-26 04:11:13,265 INFO [main] org.eclipse.jetty.server.Server: Started @1990ms
2025-03-26 04:11:13,265 INFO [main] org.apache.hadoop.yarn.webapp.WebApps: Web app cluster started at 8088
2025-03-26 04:11:13,397 INFO [main] org.apache.hadoop.ipc.CallQueueManager: Using callQueue: class java.util.concurrent.LinkedBlockingQueue, queueCapacity: 100, scheduler: class org.apache.hadoop.ipc.DefaultRpcScheduler, ipcBackoff: false.
2025-03-26 04:11:13,443 INFO [Socket Reader #1 for port 8033] org.apache.hadoop.ipc.Server: Starting Socket Reader #1 for port 8033
2025-03-26 04:11:13,613 INFO [Listener at master/8033] org.apache.hadoop.yarn.factories.impl.pb.RpcServerFactoryPBImpl: Adding protocol org.apache.hadoop.yarn.server.api.ResourceManagerAdministrationProtocolPB to the server
2025-03-26 04:11:13,614 INFO [IPC Server Responder] org.apache.hadoop.ipc.Server: IPC Server Responder: starting
2025-03-26 04:11:13,614 INFO [IPC Server listener on 8033] org.apache.hadoop.ipc.Server: IPC Server listener on 8033: starting
2025-03-26 04:11:13,615 INFO [Listener at master/8033] org.apache.hadoop.yarn.server.resourcemanager.ResourceManager: Transitioning to active state
2025-03-26 04:11:13,622 INFO [Listener at master/8033] org.apache.hadoop.yarn.server.resourcemanager.recovery.RMStateStore: Updating AMRMToken
2025-03-26 04:11:13,622 INFO [Listener at master/8033] org.apache.hadoop.yarn.server.resourcemanager.security.RMContainerTokenSecretManager: Rolling master-key for container-tokens
2025-03-26 04:11:13,622 INFO [Listener at master/8033] org.apache.hadoop.yarn.server.resourcemanager.security.NMTokenSecretManagerInRM: Rolling master-key for nm-tokens
2025-03-26 04:11:13,622 INFO [Listener at master/8033] org.apache.hadoop.security.token.delegation.AbstractDelegationTokenSecretManager: Updating the current master key for generating delegation tokens
2025-03-26 04:11:13,622 INFO [Listener at master/8033] org.apache.hadoop.yarn.server.resourcemanager.security.RMDelegationTokenSecretManager: storing master key with keyID 1
2025-03-26 04:11:13,622 INFO [Listener at master/8033] org.apache.hadoop.yarn.server.resourcemanager.recovery.RMStateStore: Storing RMDTMasterKey.
2025-03-26 04:11:13,624 INFO [Thread[Thread-28,5,main]] org.apache.hadoop.security.token.delegation.AbstractDelegationTokenSecretManager: Starting expired delegation token remover thread, tokenRemoverScanInterval=60 min(s)
2025-03-26 04:11:13,624 INFO [Thread[Thread-28,5,main]] org.apache.hadoop.security.token.delegation.AbstractDelegationTokenSecretManager: Updating the current master key for generating delegation tokens
2025-03-26 04:11:13,624 INFO [Thread[Thread-28,5,main]] org.apache.hadoop.yarn.server.resourcemanager.security.RMDelegationTokenSecretManager: storing master key with keyID 2
2025-03-26 04:11:13,624 INFO [Thread[Thread-28,5,main]] org.apache.hadoop.yarn.server.resourcemanager.recovery.RMStateStore: Storing RMDTMasterKey.
2025-03-26 04:11:13,624 INFO [Listener at master/8033] org.apache.hadoop.yarn.event.AsyncDispatcher: Registering class org.apache.hadoop.yarn.nodelabels.event.NodeLabelsStoreEventType for class org.apache.hadoop.yarn.nodelabels.CommonNodeLabelsManager$ForwardingEventHandler
2025-03-26 04:11:13,689 INFO [Listener at master/8033] org.apache.hadoop.yarn.nodelabels.store.AbstractFSNodeStore: Created store directory :file:/tmp/hadoop-yarn-root/node-attribute
2025-03-26 04:11:13,708 INFO [Listener at master/8033] org.apache.hadoop.yarn.nodelabels.store.AbstractFSNodeStore: Finished write mirror at:file:/tmp/hadoop-yarn-root/node-attribute/nodeattribute.mirror
2025-03-26 04:11:13,708 INFO [Listener at master/8033] org.apache.hadoop.yarn.nodelabels.store.AbstractFSNodeStore: Finished create editlog file at:file:/tmp/hadoop-yarn-root/node-attribute/nodeattribute.editlog
2025-03-26 04:11:13,721 INFO [Listener at master/8033] org.apache.hadoop.yarn.event.AsyncDispatcher: Registering class org.apache.hadoop.yarn.server.resourcemanager.nodelabels.NodeAttributesStoreEventType for class org.apache.hadoop.yarn.server.resourcemanager.nodelabels.NodeAttributesManagerImpl$ForwardingEventHandler
2025-03-26 04:11:13,721 INFO [Listener at master/8033] org.apache.hadoop.yarn.server.resourcemanager.scheduler.placement.MultiNodeSortingManager: Starting NodeSortingService=MultiNodeSortingManager
2025-03-26 04:11:13,727 INFO [Listener at master/8033] org.apache.hadoop.ipc.CallQueueManager: Using callQueue: class java.util.concurrent.LinkedBlockingQueue, queueCapacity: 5000, scheduler: class org.apache.hadoop.ipc.DefaultRpcScheduler, ipcBackoff: false.
2025-03-26 04:11:13,727 INFO [Socket Reader #1 for port 8031] org.apache.hadoop.ipc.Server: Starting Socket Reader #1 for port 8031
2025-03-26 04:11:13,729 INFO [Listener at master/8031] org.apache.hadoop.yarn.factories.impl.pb.RpcServerFactoryPBImpl: Adding protocol org.apache.hadoop.yarn.server.api.ResourceTrackerPB to the server
2025-03-26 04:11:13,729 INFO [IPC Server Responder] org.apache.hadoop.ipc.Server: IPC Server Responder: starting
2025-03-26 04:11:13,730 INFO [IPC Server listener on 8031] org.apache.hadoop.ipc.Server: IPC Server listener on 8031: starting
2025-03-26 04:11:13,735 INFO [org.apache.hadoop.util.JvmPauseMonitor$Monitor@221a2068] org.apache.hadoop.util.JvmPauseMonitor: Starting JVM pause monitor
2025-03-26 04:11:13,740 INFO [Listener at master/8031] org.apache.hadoop.ipc.CallQueueManager: Using callQueue: class java.util.concurrent.LinkedBlockingQueue, queueCapacity: 5000, scheduler: class org.apache.hadoop.ipc.DefaultRpcScheduler, ipcBackoff: false.
2025-03-26 04:11:13,743 INFO [Socket Reader #1 for port 8030] org.apache.hadoop.ipc.Server: Starting Socket Reader #1 for port 8030
2025-03-26 04:11:13,746 INFO [Listener at master/8030] org.apache.hadoop.yarn.factories.impl.pb.RpcServerFactoryPBImpl: Adding protocol org.apache.hadoop.yarn.api.ApplicationMasterProtocolPB to the server
2025-03-26 04:11:13,746 INFO [IPC Server Responder] org.apache.hadoop.ipc.Server: IPC Server Responder: starting
2025-03-26 04:11:13,747 INFO [IPC Server listener on 8030] org.apache.hadoop.ipc.Server: IPC Server listener on 8030: starting
2025-03-26 04:11:13,794 INFO [Listener at master/8030] org.apache.hadoop.ipc.CallQueueManager: Using callQueue: class java.util.concurrent.LinkedBlockingQueue, queueCapacity: 5000, scheduler: class org.apache.hadoop.ipc.DefaultRpcScheduler, ipcBackoff: false.
2025-03-26 04:11:13,798 INFO [Socket Reader #1 for port 8032] org.apache.hadoop.ipc.Server: Starting Socket Reader #1 for port 8032
2025-03-26 04:11:13,800 INFO [Listener at master/8032] org.apache.hadoop.yarn.factories.impl.pb.RpcServerFactoryPBImpl: Adding protocol org.apache.hadoop.yarn.api.ApplicationClientProtocolPB to the server
2025-03-26 04:11:13,801 INFO [IPC Server Responder] org.apache.hadoop.ipc.Server: IPC Server Responder: starting
2025-03-26 04:11:13,801 INFO [IPC Server listener on 8032] org.apache.hadoop.ipc.Server: IPC Server listener on 8032: starting
2025-03-26 04:11:14,100 INFO [Listener at master/8032] org.apache.hadoop.yarn.server.webproxy.ProxyCA: Created Certificate for OU=YARN-a0a7e8c8-d856-43db-83b0-3a14187bdfc3
2025-03-26 04:11:14,174 INFO [Listener at master/8032] org.apache.hadoop.yarn.server.resourcemanager.recovery.RMStateStore: Storing CA Certificate and Private Key
2025-03-26 04:11:14,174 INFO [Listener at master/8032] org.apache.hadoop.yarn.server.resourcemanager.ResourceManager: Transitioned to active state
2025-03-26 04:11:16,166 INFO [IPC Server handler 2 on default port 8031] org.apache.hadoop.yarn.server.resourcemanager.ResourceTrackerService: NodeManager from node slave1(cmPort: 39069 httpPort: 8042) registered with capability: <memory:8192, vCores:8>, assigned nodeId slave1:39069
2025-03-26 04:11:16,170 INFO [IPC Server handler 1 on default port 8031] org.apache.hadoop.yarn.server.resourcemanager.ResourceTrackerService: NodeManager from node slave2(cmPort: 42879 httpPort: 8042) registered with capability: <memory:8192, vCores:8>, assigned nodeId slave2:42879
2025-03-26 04:11:16,172 INFO [RM Event dispatcher] org.apache.hadoop.yarn.server.resourcemanager.rmnode.RMNodeImpl: slave1:39069 Node Transitioned from NEW to RUNNING
2025-03-26 04:11:16,173 INFO [RM Event dispatcher] org.apache.hadoop.yarn.server.resourcemanager.rmnode.RMNodeImpl: slave2:42879 Node Transitioned from NEW to RUNNING
2025-03-26 04:11:16,193 INFO [RM Event dispatcher] org.apache.hadoop.yarn.server.resourcemanager.rmnode.RMNodeImpl: slave0:45449 Node Transitioned from NEW to RUNNING
2025-03-26 04:11:16,193 INFO [IPC Server handler 0 on default port 8031] org.apache.hadoop.yarn.server.resourcemanager.ResourceTrackerService: NodeManager from node slave0(cmPort: 45449 httpPort: 8042) registered with capability: <memory:8192, vCores:8>, assigned nodeId slave0:45449
2025-03-26 04:11:16,237 INFO [SchedulerEventDispatcher:Event Processor] org.apache.hadoop.yarn.server.resourcemanager.scheduler.capacity.CapacityScheduler: Added node slave1:39069 clusterResource: <memory:8192, vCores:8>
2025-03-26 04:11:16,239 INFO [SchedulerEventDispatcher:Event Processor] org.apache.hadoop.yarn.server.resourcemanager.scheduler.capacity.CapacityScheduler: Added node slave2:42879 clusterResource: <memory:16384, vCores:16>
2025-03-26 04:11:16,242 INFO [SchedulerEventDispatcher:Event Processor] org.apache.hadoop.yarn.server.resourcemanager.scheduler.capacity.CapacityScheduler: Added node slave0:45449 clusterResource: <memory:24576, vCores:24>
2025-03-26 04:12:00,862 INFO [IPC Server handler 5 on default port 8032] org.apache.hadoop.yarn.server.resourcemanager.ClientRMService: Allocated new applicationId: 1
2025-03-26 04:12:04,348 INFO [IPC Server handler 8 on default port 8032] org.apache.hadoop.yarn.server.resourcemanager.scheduler.capacity.CapacityScheduler: Application 'application_1742962273615_0001' is submitted without priority hence considering default queue/cluster priority: 0
2025-03-26 04:12:04,348 INFO [IPC Server handler 8 on default port 8032] org.apache.hadoop.yarn.server.resourcemanager.scheduler.capacity.CapacityScheduler: Priority '0' is acceptable in queue : default for application: application_1742962273615_0001
2025-03-26 04:12:04,358 WARN [IPC Server handler 8 on default port 8032] org.apache.hadoop.yarn.server.resourcemanager.rmapp.RMAppImpl: The specific max attempts: 0 for application: 1 is invalid, because it is less than or equal to zero. Use the rm max attempts instead.
2025-03-26 04:12:04,359 INFO [IPC Server handler 8 on default port 8032] org.apache.hadoop.yarn.server.resourcemanager.ClientRMService: Application with id 1 submitted by user root
2025-03-26 04:12:04,359 INFO [RM Event dispatcher] org.apache.hadoop.yarn.server.resourcemanager.rmapp.RMAppImpl: Storing application with id application_1742962273615_0001
2025-03-26 04:12:04,365 INFO [RM Event dispatcher] org.apache.hadoop.yarn.server.resourcemanager.rmapp.RMAppImpl: application_1742962273615_0001 State change from NEW to NEW_SAVING on event = START
2025-03-26 04:12:04,365 INFO [RM StateStore dispatcher] org.apache.hadoop.yarn.server.resourcemanager.recovery.RMStateStore: Storing info for app: application_1742962273615_0001
2025-03-26 04:12:04,366 INFO [RM Event dispatcher] org.apache.hadoop.yarn.server.resourcemanager.rmapp.RMAppImpl: application_1742962273615_0001 State change from NEW_SAVING to SUBMITTED on event = APP_NEW_SAVED
2025-03-26 04:12:04,368 INFO [SchedulerEventDispatcher:Event Processor] org.apache.hadoop.yarn.server.resourcemanager.scheduler.capacity.ParentQueue: Application added - appId: application_1742962273615_0001 user: root leaf-queue of parent: root #applications: 1
2025-03-26 04:12:04,378 INFO [SchedulerEventDispatcher:Event Processor] org.apache.hadoop.yarn.server.resourcemanager.scheduler.capacity.CapacityScheduler: Accepted application application_1742962273615_0001 from user: root, in queue: default
2025-03-26 04:12:04,390 INFO [RM Event dispatcher] org.apache.hadoop.yarn.server.resourcemanager.rmapp.RMAppImpl: application_1742962273615_0001 State change from SUBMITTED to ACCEPTED on event = APP_ACCEPTED
2025-03-26 04:12:04,401 INFO [RM Event dispatcher] org.apache.hadoop.yarn.server.resourcemanager.ApplicationMasterService: Registering app attempt : appattempt_1742962273615_0001_000001
2025-03-26 04:12:04,401 INFO [RM Event dispatcher] org.apache.hadoop.yarn.server.resourcemanager.rmapp.attempt.RMAppAttemptImpl: appattempt_1742962273615_0001_000001 State change from NEW to SUBMITTED on event = START
2025-03-26 04:12:04,450 WARN [SchedulerEventDispatcher:Event Processor] org.apache.hadoop.yarn.server.resourcemanager.scheduler.capacity.LeafQueue: maximum-am-resource-percent is insufficient to start a single application in queue, it is likely set too low. skipping enforcement to allow at least one application to start
2025-03-26 04:12:04,451 WARN [SchedulerEventDispatcher:Event Processor] org.apache.hadoop.yarn.server.resourcemanager.scheduler.capacity.LeafQueue: maximum-am-resource-percent is insufficient to start a single application in queue for user, it is likely set too low. skipping enforcement to allow at least one application to start
2025-03-26 04:12:04,452 INFO [SchedulerEventDispatcher:Event Processor] org.apache.hadoop.yarn.server.resourcemanager.scheduler.capacity.LeafQueue: Application application_1742962273615_0001 from user: root activated in queue: root.default
2025-03-26 04:12:04,452 INFO [SchedulerEventDispatcher:Event Processor] org.apache.hadoop.yarn.server.resourcemanager.scheduler.capacity.LeafQueue: Application added - appId: application_1742962273615_0001 user: root, leaf-queue: root.default #user-pending-applications: 0 #user-active-applications: 1 #queue-pending-applications: 0 #queue-active-applications: 1 #queue-nonrunnable-applications: 0
2025-03-26 04:12:04,452 INFO [SchedulerEventDispatcher:Event Processor] org.apache.hadoop.yarn.server.resourcemanager.scheduler.capacity.CapacityScheduler: Added Application Attempt appattempt_1742962273615_0001_000001 to scheduler from user root in queue root.default
2025-03-26 04:12:04,459 INFO [RM Event dispatcher] org.apache.hadoop.yarn.server.resourcemanager.rmapp.attempt.RMAppAttemptImpl: appattempt_1742962273615_0001_000001 State change from SUBMITTED to SCHEDULED on event = ATTEMPT_ADDED
2025-03-26 04:12:05,366 INFO [SchedulerEventDispatcher:Event Processor] org.apache.hadoop.yarn.server.resourcemanager.scheduler.capacity.allocator.AbstractContainerAllocator: assignedContainer application attempt=appattempt_1742962273615_0001_000001 container=null queue=default clusterResource=<memory:24576, vCores:24> type=OFF_SWITCH requestedPartition=
2025-03-26 04:12:05,367 INFO [SchedulerEventDispatcher:Event Processor] org.apache.hadoop.yarn.server.resourcemanager.rmcontainer.RMContainerImpl: container_1742962273615_0001_01_000001 Container Transitioned from NEW to ALLOCATED
2025-03-26 04:12:05,368 INFO [SchedulerEventDispatcher:Event Processor] org.apache.hadoop.yarn.server.resourcemanager.scheduler.common.fica.FiCaSchedulerNode: Assigned container container_1742962273615_0001_01_000001 of capacity <memory:5120, vCores:1> on host slave2:42879, which has 1 containers, <memory:5120, vCores:1> used and <memory:3072, vCores:7> available after allocation
2025-03-26 04:12:05,368 INFO [SchedulerEventDispatcher:Event Processor] org.apache.hadoop.yarn.server.resourcemanager.scheduler.capacity.ParentQueue: assignedContainer queue=root usedCapacity=0.20833333 absoluteUsedCapacity=0.20833333 used=<memory:5120, vCores:1> cluster=<memory:24576, vCores:24>
2025-03-26 04:12:05,368 INFO [SchedulerEventDispatcher:Event Processor] org.apache.hadoop.yarn.server.resourcemanager.scheduler.capacity.CapacityScheduler: Allocation proposal accepted
2025-03-26 04:12:05,379 INFO [RM Event dispatcher] org.apache.hadoop.yarn.server.resourcemanager.rmcontainer.RMContainerImpl: container_1742962273615_0001_01_000001 Container Transitioned from ALLOCATED to ACQUIRED
2025-03-26 04:12:05,379 INFO [RM Event dispatcher] org.apache.hadoop.yarn.server.resourcemanager.security.NMTokenSecretManagerInRM: Clear node set for appattempt_1742962273615_0001_000001
2025-03-26 04:12:05,379 INFO [RM Event dispatcher] org.apache.hadoop.yarn.server.resourcemanager.rmapp.attempt.RMAppAttemptImpl: Storing attempt: AppId: application_1742962273615_0001 AttemptId: appattempt_1742962273615_0001_000001 MasterContainer: Container: [ContainerId: container_1742962273615_0001_01_000001, AllocationRequestId: -1, Version: 0, NodeId: slave2:42879, NodeHttpAddress: slave2:8042, Resource: <memory:5120, vCores:1>, Priority: 0, Token: Token { kind: ContainerToken, service: 172.20.1.13:42879 }, ExecutionType: GUARANTEED, ]
2025-03-26 04:12:05,385 INFO [RM Event dispatcher] org.apache.hadoop.yarn.server.resourcemanager.rmapp.attempt.RMAppAttemptImpl: appattempt_1742962273615_0001_000001 State change from SCHEDULED to ALLOCATED_SAVING on event = CONTAINER_ALLOCATED
2025-03-26 04:12:05,387 INFO [RM Event dispatcher] org.apache.hadoop.yarn.server.resourcemanager.rmapp.attempt.RMAppAttemptImpl: appattempt_1742962273615_0001_000001 State change from ALLOCATED_SAVING to ALLOCATED on event = ATTEMPT_NEW_SAVED
2025-03-26 04:12:05,403 INFO [ApplicationMasterLauncher #0] org.apache.hadoop.yarn.server.resourcemanager.amlauncher.AMLauncher: Launching masterappattempt_1742962273615_0001_000001
2025-03-26 04:12:05,442 INFO [ApplicationMasterLauncher #0] org.apache.hadoop.yarn.server.resourcemanager.amlauncher.AMLauncher: Setting up container Container: [ContainerId: container_1742962273615_0001_01_000001, AllocationRequestId: -1, Version: 0, NodeId: slave2:42879, NodeHttpAddress: slave2:8042, Resource: <memory:5120, vCores:1>, Priority: 0, Token: Token { kind: ContainerToken, service: 172.20.1.13:42879 }, ExecutionType: GUARANTEED, ] for AM appattempt_1742962273615_0001_000001
2025-03-26 04:12:05,442 INFO [ApplicationMasterLauncher #0] org.apache.hadoop.yarn.server.resourcemanager.security.AMRMTokenSecretManager: Create AMRMToken for ApplicationAttempt: appattempt_1742962273615_0001_000001
2025-03-26 04:12:05,444 INFO [ApplicationMasterLauncher #0] org.apache.hadoop.yarn.server.resourcemanager.security.AMRMTokenSecretManager: Creating password for appattempt_1742962273615_0001_000001
2025-03-26 04:12:05,594 INFO [ApplicationMasterLauncher #0] org.apache.hadoop.yarn.server.resourcemanager.amlauncher.AMLauncher: Done launching container Container: [ContainerId: container_1742962273615_0001_01_000001, AllocationRequestId: -1, Version: 0, NodeId: slave2:42879, NodeHttpAddress: slave2:8042, Resource: <memory:5120, vCores:1>, Priority: 0, Token: Token { kind: ContainerToken, service: 172.20.1.13:42879 }, ExecutionType: GUARANTEED, ] for AM appattempt_1742962273615_0001_000001
2025-03-26 04:12:05,594 INFO [RM Event dispatcher] org.apache.hadoop.yarn.server.resourcemanager.rmapp.attempt.RMAppAttemptImpl: appattempt_1742962273615_0001_000001 State change from ALLOCATED to LAUNCHED on event = LAUNCHED
2025-03-26 04:12:05,594 INFO [RM Event dispatcher] org.apache.hadoop.yarn.server.resourcemanager.rmapp.RMAppImpl: update the launch time for applicationId: application_1742962273615_0001, attemptId: appattempt_1742962273615_0001_000001launchTime: 1742962325594
2025-03-26 04:12:05,594 INFO [RM StateStore dispatcher] org.apache.hadoop.yarn.server.resourcemanager.recovery.RMStateStore: Updating info for app: application_1742962273615_0001
2025-03-26 04:12:06,380 INFO [SchedulerEventDispatcher:Event Processor] org.apache.hadoop.yarn.server.resourcemanager.rmcontainer.RMContainerImpl: container_1742962273615_0001_01_000001 Container Transitioned from ACQUIRED to RUNNING
2025-03-26 04:12:09,924 INFO [Socket Reader #1 for port 8030] SecurityLogger.org.apache.hadoop.ipc.Server: Auth successful for appattempt_1742962273615_0001_000001 (auth:SIMPLE) from 172.20.1.13:44072
2025-03-26 04:12:09,939 INFO [IPC Server handler 7 on default port 8030] org.apache.hadoop.yarn.server.resourcemanager.DefaultAMSProcessor: AM registration appattempt_1742962273615_0001_000001
2025-03-26 04:12:09,940 INFO [RM Event dispatcher] org.apache.hadoop.yarn.server.resourcemanager.rmapp.attempt.RMAppAttemptImpl: appattempt_1742962273615_0001_000001 State change from LAUNCHED to RUNNING on event = REGISTERED
2025-03-26 04:12:09,940 INFO [RM Event dispatcher] org.apache.hadoop.yarn.server.resourcemanager.rmapp.RMAppImpl: application_1742962273615_0001 State change from ACCEPTED to RUNNING on event = ATTEMPT_REGISTERED
2025-03-26 04:12:10,363 INFO [SchedulerEventDispatcher:Event Processor] org.apache.hadoop.yarn.server.resourcemanager.scheduler.capacity.allocator.AbstractContainerAllocator: assignedContainer application attempt=appattempt_1742962273615_0001_000001 container=null queue=default clusterResource=<memory:24576, vCores:24> type=OFF_SWITCH requestedPartition=
2025-03-26 04:12:10,365 INFO [SchedulerEventDispatcher:Event Processor] org.apache.hadoop.yarn.server.resourcemanager.rmcontainer.RMContainerImpl: container_1742962273615_0001_01_000002 Container Transitioned from NEW to ALLOCATED
2025-03-26 04:12:10,365 INFO [SchedulerEventDispatcher:Event Processor] org.apache.hadoop.yarn.server.resourcemanager.scheduler.common.fica.FiCaSchedulerNode: Assigned container container_1742962273615_0001_01_000002 of capacity <memory:3072, vCores:1> on host slave1:39069, which has 1 containers, <memory:3072, vCores:1> used and <memory:5120, vCores:7> available after allocation
2025-03-26 04:12:10,366 INFO [SchedulerEventDispatcher:Event Processor] org.apache.hadoop.yarn.server.resourcemanager.scheduler.capacity.ParentQueue: assignedContainer queue=root usedCapacity=0.33333334 absoluteUsedCapacity=0.33333334 used=<memory:8192, vCores:2> cluster=<memory:24576, vCores:24>
2025-03-26 04:12:10,366 INFO [SchedulerEventDispatcher:Event Processor] org.apache.hadoop.yarn.server.resourcemanager.scheduler.capacity.CapacityScheduler: Allocation proposal accepted
2025-03-26 04:12:10,371 INFO [SchedulerEventDispatcher:Event Processor] org.apache.hadoop.yarn.server.resourcemanager.scheduler.capacity.allocator.AbstractContainerAllocator: assignedContainer application attempt=appattempt_1742962273615_0001_000001 container=null queue=default clusterResource=<memory:24576, vCores:24> type=OFF_SWITCH requestedPartition=
2025-03-26 04:12:10,372 INFO [SchedulerEventDispatcher:Event Processor] org.apache.hadoop.yarn.server.resourcemanager.rmcontainer.RMContainerImpl: container_1742962273615_0001_01_000003 Container Transitioned from NEW to ALLOCATED
2025-03-26 04:12:10,372 INFO [SchedulerEventDispatcher:Event Processor] org.apache.hadoop.yarn.server.resourcemanager.scheduler.common.fica.FiCaSchedulerNode: Assigned container container_1742962273615_0001_01_000003 of capacity <memory:3072, vCores:1> on host slave0:45449, which has 1 containers, <memory:3072, vCores:1> used and <memory:5120, vCores:7> available after allocation
2025-03-26 04:12:10,372 INFO [SchedulerEventDispatcher:Event Processor] org.apache.hadoop.yarn.server.resourcemanager.scheduler.capacity.ParentQueue: assignedContainer queue=root usedCapacity=0.45833334 absoluteUsedCapacity=0.45833334 used=<memory:11264, vCores:3> cluster=<memory:24576, vCores:24>
2025-03-26 04:12:10,373 INFO [SchedulerEventDispatcher:Event Processor] org.apache.hadoop.yarn.server.resourcemanager.scheduler.capacity.CapacityScheduler: Allocation proposal accepted
2025-03-26 04:12:10,390 INFO [SchedulerEventDispatcher:Event Processor] org.apache.hadoop.yarn.server.resourcemanager.scheduler.capacity.allocator.AbstractContainerAllocator: assignedContainer application attempt=appattempt_1742962273615_0001_000001 container=null queue=default clusterResource=<memory:24576, vCores:24> type=OFF_SWITCH requestedPartition=
2025-03-26 04:12:10,391 INFO [SchedulerEventDispatcher:Event Processor] org.apache.hadoop.yarn.server.resourcemanager.rmcontainer.RMContainerImpl: container_1742962273615_0001_01_000004 Container Transitioned from NEW to ALLOCATED
2025-03-26 04:12:10,391 INFO [SchedulerEventDispatcher:Event Processor] org.apache.hadoop.yarn.server.resourcemanager.scheduler.common.fica.FiCaSchedulerNode: Assigned container container_1742962273615_0001_01_000004 of capacity <memory:3072, vCores:1> on host slave2:42879, which has 2 containers, <memory:8192, vCores:2> used and <memory:0, vCores:6> available after allocation
2025-03-26 04:12:10,392 INFO [SchedulerEventDispatcher:Event Processor] org.apache.hadoop.yarn.server.resourcemanager.scheduler.capacity.ParentQueue: assignedContainer queue=root usedCapacity=0.5833333 absoluteUsedCapacity=0.5833333 used=<memory:14336, vCores:4> cluster=<memory:24576, vCores:24>
2025-03-26 04:12:10,392 INFO [SchedulerEventDispatcher:Event Processor] org.apache.hadoop.yarn.server.resourcemanager.scheduler.capacity.CapacityScheduler: Allocation proposal accepted
2025-03-26 04:12:10,506 INFO [IPC Server handler 28 on default port 8030] org.apache.hadoop.yarn.server.resourcemanager.rmcontainer.RMContainerImpl: container_1742962273615_0001_01_000002 Container Transitioned from ALLOCATED to ACQUIRED
2025-03-26 04:12:10,507 INFO [IPC Server handler 28 on default port 8030] org.apache.hadoop.yarn.server.resourcemanager.rmcontainer.RMContainerImpl: container_1742962273615_0001_01_000003 Container Transitioned from ALLOCATED to ACQUIRED
2025-03-26 04:12:10,507 INFO [IPC Server handler 28 on default port 8030] org.apache.hadoop.yarn.server.resourcemanager.rmcontainer.RMContainerImpl: container_1742962273615_0001_01_000004 Container Transitioned from ALLOCATED to ACQUIRED
2025-03-26 04:12:11,375 INFO [SchedulerEventDispatcher:Event Processor] org.apache.hadoop.yarn.server.resourcemanager.rmcontainer.RMContainerImpl: container_1742962273615_0001_01_000003 Container Transitioned from ACQUIRED to RUNNING
2025-03-26 04:12:11,375 INFO [SchedulerEventDispatcher:Event Processor] org.apache.hadoop.yarn.server.resourcemanager.rmcontainer.RMContainerImpl: container_1742962273615_0001_01_000002 Container Transitioned from ACQUIRED to RUNNING
2025-03-26 04:12:11,392 INFO [SchedulerEventDispatcher:Event Processor] org.apache.hadoop.yarn.server.resourcemanager.rmcontainer.RMContainerImpl: container_1742962273615_0001_01_000004 Container Transitioned from ACQUIRED to RUNNING
2025-03-26 04:12:13,528 INFO [IPC Server handler 18 on default port 8030] org.apache.hadoop.yarn.server.resourcemanager.scheduler.AppSchedulingInfo: checking for deactivate of application :application_1742962273615_0001
2025-03-26 04:12:19,886 INFO [SchedulerEventDispatcher:Event Processor] org.apache.hadoop.yarn.server.resourcemanager.rmcontainer.RMContainerImpl: container_1742962273615_0001_01_000003 Container Transitioned from RUNNING to COMPLETED
2025-03-26 04:12:19,892 INFO [SchedulerEventDispatcher:Event Processor] org.apache.hadoop.yarn.server.resourcemanager.rmcontainer.RMContainerImpl: container_1742962273615_0001_01_000002 Container Transitioned from RUNNING to COMPLETED
2025-03-26 04:12:19,964 INFO [RM Event dispatcher] org.apache.hadoop.yarn.server.resourcemanager.rmapp.attempt.RMAppAttemptImpl: Updating application attempt appattempt_1742962273615_0001_000001 with final state: FINISHING, and exit status: -1000
2025-03-26 04:12:19,964 INFO [RM Event dispatcher] org.apache.hadoop.yarn.server.resourcemanager.rmapp.attempt.RMAppAttemptImpl: appattempt_1742962273615_0001_000001 State change from RUNNING to FINAL_SAVING on event = UNREGISTERED
2025-03-26 04:12:19,964 INFO [RM Event dispatcher] org.apache.hadoop.yarn.server.resourcemanager.rmapp.RMAppImpl: Updating application application_1742962273615_0001 with final state: FINISHING
2025-03-26 04:12:19,965 INFO [RM StateStore dispatcher] org.apache.hadoop.yarn.server.resourcemanager.recovery.RMStateStore: Updating info for app: application_1742962273615_0001
2025-03-26 04:12:19,965 INFO [RM Event dispatcher] org.apache.hadoop.yarn.server.resourcemanager.rmapp.RMAppImpl: application_1742962273615_0001 State change from RUNNING to FINAL_SAVING on event = ATTEMPT_UNREGISTERED
2025-03-26 04:12:19,965 INFO [RM Event dispatcher] org.apache.hadoop.yarn.server.resourcemanager.rmapp.attempt.RMAppAttemptImpl: appattempt_1742962273615_0001_000001 State change from FINAL_SAVING to FINISHING on event = ATTEMPT_UPDATE_SAVED
2025-03-26 04:12:19,966 INFO [RM Event dispatcher] org.apache.hadoop.yarn.server.resourcemanager.rmapp.RMAppImpl: application_1742962273615_0001 State change from FINAL_SAVING to FINISHING on event = APP_UPDATE_SAVED
2025-03-26 04:12:19,966 INFO [SchedulerEventDispatcher:Event Processor] org.apache.hadoop.yarn.server.resourcemanager.rmcontainer.RMContainerImpl: container_1742962273615_0001_01_000004 Container Transitioned from RUNNING to COMPLETED
2025-03-26 04:12:20,070 INFO [IPC Server handler 11 on default port 8030] org.apache.hadoop.yarn.server.resourcemanager.ApplicationMasterService: application_1742962273615_0001 unregistered successfully. 
2025-03-26 04:12:20,140 INFO [SchedulerEventDispatcher:Event Processor] org.apache.hadoop.yarn.server.resourcemanager.rmcontainer.RMContainerImpl: container_1742962273615_0001_01_000001 Container Transitioned from RUNNING to COMPLETED
2025-03-26 04:12:20,140 INFO [RM Event dispatcher] org.apache.hadoop.yarn.server.resourcemanager.ApplicationMasterService: Unregistering app attempt : appattempt_1742962273615_0001_000001
2025-03-26 04:12:20,141 INFO [RM Event dispatcher] org.apache.hadoop.yarn.server.resourcemanager.security.AMRMTokenSecretManager: Application finished, removing password for appattempt_1742962273615_0001_000001
2025-03-26 04:12:20,142 INFO [RM Event dispatcher] org.apache.hadoop.yarn.server.resourcemanager.rmapp.attempt.RMAppAttemptImpl: appattempt_1742962273615_0001_000001 State change from FINISHING to FINISHED on event = CONTAINER_FINISHED
2025-03-26 04:12:20,144 INFO [RM Event dispatcher] org.apache.hadoop.yarn.server.resourcemanager.rmapp.RMAppImpl: application_1742962273615_0001 State change from FINISHING to FINISHED on event = ATTEMPT_FINISHED
2025-03-26 04:12:20,144 INFO [SchedulerEventDispatcher:Event Processor] org.apache.hadoop.yarn.server.resourcemanager.scheduler.capacity.CapacityScheduler: Application Attempt appattempt_1742962273615_0001_000001 is done. finalState=FINISHED
2025-03-26 04:12:20,144 INFO [SchedulerEventDispatcher:Event Processor] org.apache.hadoop.yarn.server.resourcemanager.scheduler.AppSchedulingInfo: Application application_1742962273615_0001 requests cleared
2025-03-26 04:12:20,145 INFO [SchedulerEventDispatcher:Event Processor] org.apache.hadoop.yarn.server.resourcemanager.scheduler.capacity.LeafQueue: Application removed - appId: application_1742962273615_0001 user: root queue: root.default #user-pending-applications: 0 #user-active-applications: 0 #queue-pending-applications: 0 #queue-active-applications: 0
2025-03-26 04:12:20,147 INFO [SchedulerEventDispatcher:Event Processor] org.apache.hadoop.yarn.server.resourcemanager.scheduler.capacity.ParentQueue: Application removed - appId: application_1742962273615_0001 user: root leaf-queue of parent: root #applications: 0
2025-03-26 04:12:20,147 INFO [ApplicationMasterLauncher #1] org.apache.hadoop.yarn.server.resourcemanager.amlauncher.AMLauncher: Cleaning master appattempt_1742962273615_0001_000001
2025-03-26 04:12:20,149 INFO [RM Event dispatcher] org.apache.hadoop.yarn.server.resourcemanager.RMAppManager$ApplicationSummary: appId=application_1742962273615_0001,name=org.apache.spark.examples.ml.DeveloperApiExample,user=root,queue=default,state=FINISHED,trackingUrl=http://master:8088/proxy/application_1742962273615_0001/,appMasterHost=slave2,submitTime=1742962324317,startTime=1742962324358,launchTime=1742962325594,finishTime=1742962339964,finalStatus=SUCCEEDED,memorySeconds=163568,vcoreSeconds=41,preemptedMemorySeconds=0,preemptedVcoreSeconds=0,preemptedAMContainers=0,preemptedNonAMContainers=0,preemptedResources=<memory:0\, vCores:0>,applicationType=SPARK,resourceSeconds=163568 MB-seconds\, 41 vcore-seconds,preemptedResourceSeconds=0 MB-seconds\, 0 vcore-seconds,applicationTags=,applicationNodeLabel=,diagnostics=,totalAllocatedContainers=4
