program=ml.DeveloperApiExample
SPARKLORD_MODE=CONFIG_INJECTION
cpu_cores=2
cpu_util=200
memory=4g
config_file_name=spark-defaults.conf
config_key=spark.shuffle.service.enabled
config_value=False

2025-03-25 12:28:04,907 INFO [main] org.apache.hadoop.yarn.server.resourcemanager.ResourceManager: STARTUP_MSG: 
/************************************************************
STARTUP_MSG: Starting ResourceManager
STARTUP_MSG:   host = master/172.20.1.14
STARTUP_MSG:   args = []
STARTUP_MSG:   version = 3.3.4
STARTUP_MSG:   build = https://github.com/apache/hadoop.git -r a585a73c3e02ac62350c136643a5e7f6095a3dbb; compiled by 'stevel' on 2022-07-29T12:32Z
STARTUP_MSG:   java = 1.8.0_432
************************************************************/
2025-03-25 12:28:04,912 INFO [main] org.apache.hadoop.yarn.server.resourcemanager.ResourceManager: registered UNIX signal handlers for [TERM, HUP, INT]
2025-03-25 12:28:05,210 INFO [main] org.apache.hadoop.yarn.server.resourcemanager.RMNMInfo: Registered RMInfo MBean
2025-03-25 12:28:05,215 INFO [main] org.apache.hadoop.conf.Configuration: found resource core-site.xml at file:/hadoop/etc/hadoop/core-site.xml
2025-03-25 12:28:05,257 INFO [main] org.apache.hadoop.conf.Configuration: resource-types.xml not found
2025-03-25 12:28:05,257 INFO [main] org.apache.hadoop.yarn.util.resource.ResourceUtils: Unable to find 'resource-types.xml'.
2025-03-25 12:28:05,280 INFO [main] org.apache.hadoop.conf.Configuration: found resource yarn-site.xml at file:/hadoop/etc/hadoop/yarn-site.xml
2025-03-25 12:28:05,286 INFO [main] org.apache.hadoop.yarn.metrics.GenericEventTypeMetrics: Registering GenericEventTypeMetrics
2025-03-25 12:28:05,287 INFO [main] org.apache.hadoop.yarn.event.AsyncDispatcher: Registering class org.apache.hadoop.yarn.server.resourcemanager.RMFatalEventType for class org.apache.hadoop.yarn.server.resourcemanager.ResourceManager$RMFatalEventDispatcher
2025-03-25 12:28:05,319 INFO [main] org.apache.hadoop.yarn.server.resourcemanager.security.NMTokenSecretManagerInRM: NMTokenKeyRollingInterval: 86400000ms and NMTokenKeyActivationDelay: 900000ms
2025-03-25 12:28:05,323 INFO [main] org.apache.hadoop.yarn.server.resourcemanager.security.RMContainerTokenSecretManager: ContainerTokenKeyRollingInterval: 86400000ms and ContainerTokenKeyActivationDelay: 900000ms
2025-03-25 12:28:05,330 INFO [main] org.apache.hadoop.yarn.server.resourcemanager.security.AMRMTokenSecretManager: AMRMTokenKeyRollingInterval: 86400000ms and AMRMTokenKeyActivationDelay: 900000 ms
2025-03-25 12:28:05,352 INFO [main] org.apache.hadoop.yarn.event.AsyncDispatcher: Registering class org.apache.hadoop.yarn.server.resourcemanager.recovery.RMStateStoreEventType for class org.apache.hadoop.yarn.server.resourcemanager.recovery.RMStateStore$ForwardingEventHandler
2025-03-25 12:28:05,353 INFO [main] org.apache.hadoop.yarn.event.AsyncDispatcher: Registering class org.apache.hadoop.yarn.server.resourcemanager.NodesListManagerEventType for class org.apache.hadoop.yarn.server.resourcemanager.NodesListManager
2025-03-25 12:28:05,353 INFO [main] org.apache.hadoop.yarn.server.resourcemanager.ResourceManager: Using Scheduler: org.apache.hadoop.yarn.server.resourcemanager.scheduler.capacity.CapacityScheduler
2025-03-25 12:28:05,377 INFO [main] org.apache.hadoop.yarn.event.AsyncDispatcher: Registering class org.apache.hadoop.yarn.server.resourcemanager.scheduler.event.SchedulerEventType for class org.apache.hadoop.yarn.server.resourcemanager.ResourceManager$SchedulerEventDispatcher
2025-03-25 12:28:05,377 INFO [main] org.apache.hadoop.yarn.event.AsyncDispatcher: Registering class org.apache.hadoop.yarn.server.resourcemanager.rmapp.RMAppEventType for class org.apache.hadoop.yarn.server.resourcemanager.ResourceManager$ApplicationEventDispatcher
2025-03-25 12:28:05,378 INFO [main] org.apache.hadoop.yarn.event.AsyncDispatcher: Registering class org.apache.hadoop.yarn.server.resourcemanager.rmapp.attempt.RMAppAttemptEventType for class org.apache.hadoop.yarn.server.resourcemanager.ResourceManager$ApplicationAttemptEventDispatcher
2025-03-25 12:28:05,378 INFO [main] org.apache.hadoop.yarn.event.AsyncDispatcher: Registering class org.apache.hadoop.yarn.server.resourcemanager.rmnode.RMNodeEventType for class org.apache.hadoop.yarn.server.resourcemanager.ResourceManager$NodeEventDispatcher
2025-03-25 12:28:05,424 INFO [main] org.apache.hadoop.metrics2.impl.MetricsConfig: Loaded properties from hadoop-metrics2.properties
2025-03-25 12:28:05,438 INFO [main] org.apache.hadoop.metrics2.impl.MetricsSystemImpl: Scheduled Metric snapshot period at 10 second(s).
2025-03-25 12:28:05,438 INFO [main] org.apache.hadoop.metrics2.impl.MetricsSystemImpl: ResourceManager metrics system started
2025-03-25 12:28:05,460 INFO [main] org.apache.hadoop.yarn.security.YarnAuthorizationProvider: org.apache.hadoop.yarn.security.ConfiguredYarnAuthorizer is instantiated.
2025-03-25 12:28:05,462 INFO [main] org.apache.hadoop.yarn.event.AsyncDispatcher: Registering class org.apache.hadoop.yarn.server.resourcemanager.RMAppManagerEventType for class org.apache.hadoop.yarn.server.resourcemanager.RMAppManager
2025-03-25 12:28:05,467 INFO [main] org.apache.hadoop.yarn.event.AsyncDispatcher: Registering class org.apache.hadoop.yarn.server.resourcemanager.amlauncher.AMLauncherEventType for class org.apache.hadoop.yarn.server.resourcemanager.amlauncher.ApplicationMasterLauncher
2025-03-25 12:28:05,711 INFO [main] org.apache.hadoop.yarn.server.resourcemanager.RMNMInfo: Registered RMNMInfo MBean
2025-03-25 12:28:05,712 INFO [main] org.apache.hadoop.yarn.server.resourcemanager.rmapp.monitor.RMAppLifetimeMonitor: Application lifelime monitor interval set to 3000 ms.
2025-03-25 12:28:05,714 INFO [main] org.apache.hadoop.yarn.server.resourcemanager.scheduler.placement.MultiNodeSortingManager: Initializing NodeSortingService=MultiNodeSortingManager
2025-03-25 12:28:05,715 INFO [main] org.apache.hadoop.util.HostsFileReader: Refreshing hosts (include/exclude) list
2025-03-25 12:28:05,715 INFO [main] org.apache.hadoop.util.HostsFileReader: Adding a node "172.20.1.15" to the list of included hosts from /hadoop/etc/hadoop/workers
2025-03-25 12:28:05,715 INFO [main] org.apache.hadoop.util.HostsFileReader: Adding a node "172.20.1.16" to the list of included hosts from /hadoop/etc/hadoop/workers
2025-03-25 12:28:05,715 INFO [main] org.apache.hadoop.util.HostsFileReader: Adding a node "172.20.1.17" to the list of included hosts from /hadoop/etc/hadoop/workers
2025-03-25 12:28:05,718 INFO [main] org.apache.hadoop.conf.Configuration: found resource capacity-scheduler.xml at file:/hadoop/etc/hadoop/capacity-scheduler.xml
2025-03-25 12:28:05,722 INFO [main] org.apache.hadoop.yarn.server.resourcemanager.scheduler.AbstractYarnScheduler: Minimum allocation = <memory:1024, vCores:1>
2025-03-25 12:28:05,722 INFO [main] org.apache.hadoop.yarn.server.resourcemanager.scheduler.AbstractYarnScheduler: Maximum allocation = <memory:8192, vCores:4>
2025-03-25 12:28:05,762 INFO [main] org.apache.hadoop.yarn.server.resourcemanager.scheduler.capacity.ParentQueue: root, capacity=1.0, absoluteCapacity=1.0, maxCapacity=1.0, absoluteMaxCapacity=1.0, state=RUNNING, acls=ADMINISTER_QUEUE:*SUBMIT_APP:*, labels=*,
, reservationsContinueLooking=true, orderingPolicy=utilization, priority=0
2025-03-25 12:28:05,762 INFO [main] org.apache.hadoop.yarn.server.resourcemanager.scheduler.capacity.ParentQueue: Initialized parent-queue root name=root, fullname=root
2025-03-25 12:28:05,776 INFO [main] org.apache.hadoop.yarn.server.resourcemanager.scheduler.capacity.LeafQueue: Initializing root.default
capacity = 1.0 [= (float) configuredCapacity / 100 ]
absoluteCapacity = 1.0 [= parentAbsoluteCapacity * capacity ]
maxCapacity = 1.0 [= configuredMaxCapacity ]
absoluteMaxCapacity = 1.0 [= 1.0 maximumCapacity undefined, (parentAbsoluteMaxCapacity * maximumCapacity) / 100 otherwise ]
effectiveMinResource=<memory:0, vCores:0>
 , effectiveMaxResource=<memory:0, vCores:0>
userLimit = 100 [= configuredUserLimit ]
userLimitFactor = 1.0 [= configuredUserLimitFactor ]
maxApplications = 10000 [= configuredMaximumSystemApplicationsPerQueue or (int)(configuredMaximumSystemApplications * absoluteCapacity)]
maxApplicationsPerUser = 10000 [= (int)(maxApplications * (userLimit / 100.0f) * userLimitFactor) ]
maxParallelApps = 2147483647
usedCapacity = 0.0 [= usedResourcesMemory / (clusterResourceMemory * absoluteCapacity)]
absoluteUsedCapacity = 0.0 [= usedResourcesMemory / clusterResourceMemory]
maxAMResourcePerQueuePercent = 0.1 [= configuredMaximumAMResourcePercent ]
minimumAllocationFactor = 0.875 [= (float)(maximumAllocationMemory - minimumAllocationMemory) / maximumAllocationMemory ]
maximumAllocation = <memory:8192, vCores:4> [= configuredMaxAllocation ]
numContainers = 0 [= currentNumContainers ]
state = RUNNING [= configuredState ]
acls = ADMINISTER_QUEUE:*SUBMIT_APP:* [= configuredAcls ]
nodeLocalityDelay = 40
rackLocalityAdditionalDelay = -1
labels=*,
reservationsContinueLooking = true
preemptionDisabled = true
defaultAppPriorityPerQueue = 0
priority = 0
maxLifetime = -1 seconds
defaultLifetime = -1 seconds
2025-03-25 12:28:05,778 INFO [main] org.apache.hadoop.yarn.server.resourcemanager.scheduler.capacity.CapacitySchedulerQueueManager: Initialized queue: root.default
2025-03-25 12:28:05,778 INFO [main] org.apache.hadoop.yarn.server.resourcemanager.scheduler.capacity.CapacitySchedulerQueueManager: Initialized queue: root
2025-03-25 12:28:05,780 INFO [main] org.apache.hadoop.yarn.server.resourcemanager.scheduler.capacity.CapacitySchedulerQueueManager: Initialized root queue root: numChildQueue= 1, capacity=1.0, absoluteCapacity=1.0, usedResources=<memory:0, vCores:0>usedCapacity=0.0, numApps=0, numContainers=0
2025-03-25 12:28:05,780 INFO [main] org.apache.hadoop.yarn.server.resourcemanager.placement.UserGroupMappingPlacementRule: Initialized queue mappings, override: false
2025-03-25 12:28:05,780 INFO [main] org.apache.hadoop.yarn.server.resourcemanager.scheduler.capacity.WorkflowPriorityMappingsManager: Initialized workflow priority mappings, override: false
2025-03-25 12:28:05,781 INFO [main] org.apache.hadoop.yarn.server.resourcemanager.scheduler.placement.MultiNodeSortingManager: MultiNode scheduling is 'false', and configured policies are 
2025-03-25 12:28:05,781 INFO [main] org.apache.hadoop.yarn.server.resourcemanager.scheduler.capacity.CapacityScheduler: Initialized CapacityScheduler with calculator=class org.apache.hadoop.yarn.util.resource.DefaultResourceCalculator, minimumAllocation=<<memory:1024, vCores:1>>, maximumAllocation=<<memory:8192, vCores:4>>, asynchronousScheduling=false, asyncScheduleInterval=5ms,multiNodePlacementEnabled=false, assignMultipleEnabled=true, maxAssignPerHeartbeat=100, offswitchPerHeartbeatLimit=1
2025-03-25 12:28:05,789 INFO [main] org.apache.hadoop.conf.Configuration: dynamic-resources.xml not found
2025-03-25 12:28:05,793 INFO [main] org.apache.hadoop.yarn.server.resourcemanager.AMSProcessingChain: Initializing AMS Processing chain. Root Processor=[org.apache.hadoop.yarn.server.resourcemanager.DefaultAMSProcessor].
2025-03-25 12:28:05,793 INFO [main] org.apache.hadoop.yarn.server.resourcemanager.ApplicationMasterService: disabled placement handler will be used, all scheduling requests will be rejected.
2025-03-25 12:28:05,794 INFO [main] org.apache.hadoop.yarn.server.resourcemanager.AMSProcessingChain: Adding [org.apache.hadoop.yarn.server.resourcemanager.scheduler.constraint.processor.DisabledPlacementProcessor] tp top of AMS Processing chain. 
2025-03-25 12:28:05,799 INFO [main] org.apache.hadoop.yarn.server.resourcemanager.ResourceManager: TimelineServicePublisher is not configured
2025-03-25 12:28:05,819 INFO [main] org.eclipse.jetty.util.log: Logging initialized @1196ms to org.eclipse.jetty.util.log.Slf4jLog
2025-03-25 12:28:05,912 WARN [main] org.apache.hadoop.security.authentication.server.AuthenticationFilter: Unable to initialize FileSignerSecretProvider, falling back to use random secrets. Reason: Could not read signature secret file: /root/hadoop-http-auth-signature-secret
2025-03-25 12:28:05,917 INFO [main] org.apache.hadoop.http.HttpRequestLog: Http request log for http.requests.resourcemanager is not defined
2025-03-25 12:28:05,922 INFO [main] org.apache.hadoop.http.HttpServer2: Added global filter 'safety' (class=org.apache.hadoop.http.HttpServer2$QuotingInputFilter)
2025-03-25 12:28:05,925 INFO [main] org.apache.hadoop.http.HttpServer2: Added filter RMAuthenticationFilter (class=org.apache.hadoop.yarn.server.security.http.RMAuthenticationFilter) to context cluster
2025-03-25 12:28:05,925 INFO [main] org.apache.hadoop.http.HttpServer2: Added filter RMAuthenticationFilter (class=org.apache.hadoop.yarn.server.security.http.RMAuthenticationFilter) to context logs
2025-03-25 12:28:05,925 INFO [main] org.apache.hadoop.http.HttpServer2: Added filter RMAuthenticationFilter (class=org.apache.hadoop.yarn.server.security.http.RMAuthenticationFilter) to context static
2025-03-25 12:28:05,925 INFO [main] org.apache.hadoop.http.HttpServer2: Added filter static_user_filter (class=org.apache.hadoop.http.lib.StaticUserWebFilter$StaticUserFilter) to context cluster
2025-03-25 12:28:05,925 INFO [main] org.apache.hadoop.http.HttpServer2: Added filter static_user_filter (class=org.apache.hadoop.http.lib.StaticUserWebFilter$StaticUserFilter) to context logs
2025-03-25 12:28:05,925 INFO [main] org.apache.hadoop.http.HttpServer2: Added filter static_user_filter (class=org.apache.hadoop.http.lib.StaticUserWebFilter$StaticUserFilter) to context static
2025-03-25 12:28:06,170 INFO [main] org.apache.hadoop.yarn.webapp.WebApps: Registered webapp guice modules
2025-03-25 12:28:06,173 INFO [main] org.apache.hadoop.http.HttpServer2: Jetty bound to port 8088
2025-03-25 12:28:06,174 INFO [main] org.eclipse.jetty.server.Server: jetty-9.4.43.v20210629; built: 2021-06-30T11:07:22.254Z; git: 526006ecfa3af7f1a27ef3a288e2bef7ea9dd7e8; jvm 1.8.0_432-8u432-ga~us1-0ubuntu2~24.04-ga
2025-03-25 12:28:06,190 INFO [main] org.eclipse.jetty.server.session: DefaultSessionIdManager workerName=node0
2025-03-25 12:28:06,190 INFO [main] org.eclipse.jetty.server.session: No SessionScavenger set, using defaults
2025-03-25 12:28:06,190 INFO [main] org.eclipse.jetty.server.session: node0 Scavenging every 660000ms
2025-03-25 12:28:06,199 WARN [main] org.apache.hadoop.security.authentication.server.AuthenticationFilter: Unable to initialize FileSignerSecretProvider, falling back to use random secrets. Reason: Could not read signature secret file: /root/hadoop-http-auth-signature-secret
2025-03-25 12:28:06,204 INFO [main] org.apache.hadoop.security.token.delegation.AbstractDelegationTokenSecretManager: Updating the current master key for generating delegation tokens
2025-03-25 12:28:06,209 INFO [Thread[Thread-20,5,main]] org.apache.hadoop.security.token.delegation.AbstractDelegationTokenSecretManager: Starting expired delegation token remover thread, tokenRemoverScanInterval=60 min(s)
2025-03-25 12:28:06,210 INFO [Thread[Thread-20,5,main]] org.apache.hadoop.security.token.delegation.AbstractDelegationTokenSecretManager: Updating the current master key for generating delegation tokens
2025-03-25 12:28:06,215 INFO [main] org.eclipse.jetty.server.handler.ContextHandler: Started o.e.j.s.ServletContextHandler@305a0c5f{logs,/logs,file:///hadoop/logs/,AVAILABLE}
2025-03-25 12:28:06,216 INFO [main] org.eclipse.jetty.server.handler.ContextHandler: Started o.e.j.s.ServletContextHandler@232a7d73{static,/static,jar:file:/hadoop/share/hadoop/yarn/hadoop-yarn-common-3.3.4.jar!/webapps/static,AVAILABLE}
2025-03-25 12:28:06,961 INFO [main] org.eclipse.jetty.server.handler.ContextHandler: Started o.e.j.w.WebAppContext@7add323c{cluster,/,file:///tmp/jetty-master-8088-hadoop-yarn-common-3_3_4_jar-_-any-4471631340204297945/webapp/,AVAILABLE}{jar:file:/hadoop/share/hadoop/yarn/hadoop-yarn-common-3.3.4.jar!/webapps/cluster}
2025-03-25 12:28:06,967 INFO [main] org.eclipse.jetty.server.AbstractConnector: Started ServerConnector@5b068087{HTTP/1.1, (http/1.1)}{master:8088}
2025-03-25 12:28:06,967 INFO [main] org.eclipse.jetty.server.Server: Started @2344ms
2025-03-25 12:28:06,967 INFO [main] org.apache.hadoop.yarn.webapp.WebApps: Web app cluster started at 8088
2025-03-25 12:28:07,152 INFO [main] org.apache.hadoop.ipc.CallQueueManager: Using callQueue: class java.util.concurrent.LinkedBlockingQueue, queueCapacity: 100, scheduler: class org.apache.hadoop.ipc.DefaultRpcScheduler, ipcBackoff: false.
2025-03-25 12:28:07,178 INFO [Socket Reader #1 for port 8033] org.apache.hadoop.ipc.Server: Starting Socket Reader #1 for port 8033
2025-03-25 12:28:07,273 INFO [Listener at master/8033] org.apache.hadoop.yarn.factories.impl.pb.RpcServerFactoryPBImpl: Adding protocol org.apache.hadoop.yarn.server.api.ResourceManagerAdministrationProtocolPB to the server
2025-03-25 12:28:07,273 INFO [IPC Server Responder] org.apache.hadoop.ipc.Server: IPC Server Responder: starting
2025-03-25 12:28:07,276 INFO [IPC Server listener on 8033] org.apache.hadoop.ipc.Server: IPC Server listener on 8033: starting
2025-03-25 12:28:07,277 INFO [Listener at master/8033] org.apache.hadoop.yarn.server.resourcemanager.ResourceManager: Transitioning to active state
2025-03-25 12:28:07,284 INFO [Listener at master/8033] org.apache.hadoop.yarn.server.resourcemanager.recovery.RMStateStore: Updating AMRMToken
2025-03-25 12:28:07,284 INFO [Listener at master/8033] org.apache.hadoop.yarn.server.resourcemanager.security.RMContainerTokenSecretManager: Rolling master-key for container-tokens
2025-03-25 12:28:07,284 INFO [Listener at master/8033] org.apache.hadoop.yarn.server.resourcemanager.security.NMTokenSecretManagerInRM: Rolling master-key for nm-tokens
2025-03-25 12:28:07,284 INFO [Listener at master/8033] org.apache.hadoop.security.token.delegation.AbstractDelegationTokenSecretManager: Updating the current master key for generating delegation tokens
2025-03-25 12:28:07,285 INFO [Listener at master/8033] org.apache.hadoop.yarn.server.resourcemanager.security.RMDelegationTokenSecretManager: storing master key with keyID 1
2025-03-25 12:28:07,285 INFO [Listener at master/8033] org.apache.hadoop.yarn.server.resourcemanager.recovery.RMStateStore: Storing RMDTMasterKey.
2025-03-25 12:28:07,285 INFO [Thread[Thread-28,5,main]] org.apache.hadoop.security.token.delegation.AbstractDelegationTokenSecretManager: Starting expired delegation token remover thread, tokenRemoverScanInterval=60 min(s)
2025-03-25 12:28:07,285 INFO [Thread[Thread-28,5,main]] org.apache.hadoop.security.token.delegation.AbstractDelegationTokenSecretManager: Updating the current master key for generating delegation tokens
2025-03-25 12:28:07,285 INFO [Thread[Thread-28,5,main]] org.apache.hadoop.yarn.server.resourcemanager.security.RMDelegationTokenSecretManager: storing master key with keyID 2
2025-03-25 12:28:07,285 INFO [Thread[Thread-28,5,main]] org.apache.hadoop.yarn.server.resourcemanager.recovery.RMStateStore: Storing RMDTMasterKey.
2025-03-25 12:28:07,286 INFO [Listener at master/8033] org.apache.hadoop.yarn.event.AsyncDispatcher: Registering class org.apache.hadoop.yarn.nodelabels.event.NodeLabelsStoreEventType for class org.apache.hadoop.yarn.nodelabels.CommonNodeLabelsManager$ForwardingEventHandler
2025-03-25 12:28:07,352 INFO [Listener at master/8033] org.apache.hadoop.yarn.nodelabels.store.AbstractFSNodeStore: Created store directory :file:/tmp/hadoop-yarn-root/node-attribute
2025-03-25 12:28:07,368 INFO [Listener at master/8033] org.apache.hadoop.yarn.nodelabels.store.AbstractFSNodeStore: Finished write mirror at:file:/tmp/hadoop-yarn-root/node-attribute/nodeattribute.mirror
2025-03-25 12:28:07,368 INFO [Listener at master/8033] org.apache.hadoop.yarn.nodelabels.store.AbstractFSNodeStore: Finished create editlog file at:file:/tmp/hadoop-yarn-root/node-attribute/nodeattribute.editlog
2025-03-25 12:28:07,384 INFO [Listener at master/8033] org.apache.hadoop.yarn.event.AsyncDispatcher: Registering class org.apache.hadoop.yarn.server.resourcemanager.nodelabels.NodeAttributesStoreEventType for class org.apache.hadoop.yarn.server.resourcemanager.nodelabels.NodeAttributesManagerImpl$ForwardingEventHandler
2025-03-25 12:28:07,384 INFO [Listener at master/8033] org.apache.hadoop.yarn.server.resourcemanager.scheduler.placement.MultiNodeSortingManager: Starting NodeSortingService=MultiNodeSortingManager
2025-03-25 12:28:07,391 INFO [Listener at master/8033] org.apache.hadoop.ipc.CallQueueManager: Using callQueue: class java.util.concurrent.LinkedBlockingQueue, queueCapacity: 5000, scheduler: class org.apache.hadoop.ipc.DefaultRpcScheduler, ipcBackoff: false.
2025-03-25 12:28:07,392 INFO [Socket Reader #1 for port 8031] org.apache.hadoop.ipc.Server: Starting Socket Reader #1 for port 8031
2025-03-25 12:28:07,393 INFO [Listener at master/8031] org.apache.hadoop.yarn.factories.impl.pb.RpcServerFactoryPBImpl: Adding protocol org.apache.hadoop.yarn.server.api.ResourceTrackerPB to the server
2025-03-25 12:28:07,393 INFO [IPC Server Responder] org.apache.hadoop.ipc.Server: IPC Server Responder: starting
2025-03-25 12:28:07,394 INFO [IPC Server listener on 8031] org.apache.hadoop.ipc.Server: IPC Server listener on 8031: starting
2025-03-25 12:28:07,400 INFO [org.apache.hadoop.util.JvmPauseMonitor$Monitor@221a2068] org.apache.hadoop.util.JvmPauseMonitor: Starting JVM pause monitor
2025-03-25 12:28:07,406 INFO [Listener at master/8031] org.apache.hadoop.ipc.CallQueueManager: Using callQueue: class java.util.concurrent.LinkedBlockingQueue, queueCapacity: 5000, scheduler: class org.apache.hadoop.ipc.DefaultRpcScheduler, ipcBackoff: false.
2025-03-25 12:28:07,409 INFO [Socket Reader #1 for port 8030] org.apache.hadoop.ipc.Server: Starting Socket Reader #1 for port 8030
2025-03-25 12:28:07,413 INFO [Listener at master/8030] org.apache.hadoop.yarn.factories.impl.pb.RpcServerFactoryPBImpl: Adding protocol org.apache.hadoop.yarn.api.ApplicationMasterProtocolPB to the server
2025-03-25 12:28:07,416 INFO [IPC Server Responder] org.apache.hadoop.ipc.Server: IPC Server Responder: starting
2025-03-25 12:28:07,416 INFO [IPC Server listener on 8030] org.apache.hadoop.ipc.Server: IPC Server listener on 8030: starting
2025-03-25 12:28:07,462 INFO [Listener at master/8030] org.apache.hadoop.ipc.CallQueueManager: Using callQueue: class java.util.concurrent.LinkedBlockingQueue, queueCapacity: 5000, scheduler: class org.apache.hadoop.ipc.DefaultRpcScheduler, ipcBackoff: false.
2025-03-25 12:28:07,463 INFO [Socket Reader #1 for port 8032] org.apache.hadoop.ipc.Server: Starting Socket Reader #1 for port 8032
2025-03-25 12:28:07,465 INFO [Listener at master/8032] org.apache.hadoop.yarn.factories.impl.pb.RpcServerFactoryPBImpl: Adding protocol org.apache.hadoop.yarn.api.ApplicationClientProtocolPB to the server
2025-03-25 12:28:07,466 INFO [IPC Server Responder] org.apache.hadoop.ipc.Server: IPC Server Responder: starting
2025-03-25 12:28:07,466 INFO [IPC Server listener on 8032] org.apache.hadoop.ipc.Server: IPC Server listener on 8032: starting
2025-03-25 12:28:07,767 INFO [Listener at master/8032] org.apache.hadoop.yarn.server.webproxy.ProxyCA: Created Certificate for OU=YARN-09c3e0e1-232f-4b1f-a404-bcecf5c9df13
2025-03-25 12:28:07,820 INFO [Listener at master/8032] org.apache.hadoop.yarn.server.resourcemanager.recovery.RMStateStore: Storing CA Certificate and Private Key
2025-03-25 12:28:07,821 INFO [Listener at master/8032] org.apache.hadoop.yarn.server.resourcemanager.ResourceManager: Transitioned to active state
2025-03-25 12:28:10,320 INFO [RM Event dispatcher] org.apache.hadoop.yarn.server.resourcemanager.rmnode.RMNodeImpl: slave0:33151 Node Transitioned from NEW to RUNNING
2025-03-25 12:28:10,329 INFO [IPC Server handler 0 on default port 8031] org.apache.hadoop.yarn.server.resourcemanager.ResourceTrackerService: NodeManager from node slave0(cmPort: 33151 httpPort: 8042) registered with capability: <memory:8192, vCores:8>, assigned nodeId slave0:33151
2025-03-25 12:28:10,361 INFO [SchedulerEventDispatcher:Event Processor] org.apache.hadoop.yarn.server.resourcemanager.scheduler.capacity.CapacityScheduler: Added node slave0:33151 clusterResource: <memory:8192, vCores:8>
2025-03-25 12:28:10,410 INFO [IPC Server handler 0 on default port 8031] org.apache.hadoop.yarn.server.resourcemanager.ResourceTrackerService: NodeManager from node slave1(cmPort: 37953 httpPort: 8042) registered with capability: <memory:8192, vCores:8>, assigned nodeId slave1:37953
2025-03-25 12:28:10,410 INFO [RM Event dispatcher] org.apache.hadoop.yarn.server.resourcemanager.rmnode.RMNodeImpl: slave1:37953 Node Transitioned from NEW to RUNNING
2025-03-25 12:28:10,412 INFO [SchedulerEventDispatcher:Event Processor] org.apache.hadoop.yarn.server.resourcemanager.scheduler.capacity.CapacityScheduler: Added node slave1:37953 clusterResource: <memory:16384, vCores:16>
2025-03-25 12:28:10,489 INFO [IPC Server handler 2 on default port 8031] org.apache.hadoop.yarn.server.resourcemanager.ResourceTrackerService: NodeManager from node slave2(cmPort: 46613 httpPort: 8042) registered with capability: <memory:8192, vCores:8>, assigned nodeId slave2:46613
2025-03-25 12:28:10,490 INFO [RM Event dispatcher] org.apache.hadoop.yarn.server.resourcemanager.rmnode.RMNodeImpl: slave2:46613 Node Transitioned from NEW to RUNNING
2025-03-25 12:28:10,492 INFO [SchedulerEventDispatcher:Event Processor] org.apache.hadoop.yarn.server.resourcemanager.scheduler.capacity.CapacityScheduler: Added node slave2:46613 clusterResource: <memory:24576, vCores:24>
2025-03-25 12:28:50,487 INFO [IPC Server handler 38 on default port 8032] org.apache.hadoop.yarn.server.resourcemanager.ClientRMService: Allocated new applicationId: 1
2025-03-25 12:28:54,419 INFO [IPC Server handler 0 on default port 8032] org.apache.hadoop.yarn.server.resourcemanager.scheduler.capacity.CapacityScheduler: Application 'application_1742905687277_0001' is submitted without priority hence considering default queue/cluster priority: 0
2025-03-25 12:28:54,419 INFO [IPC Server handler 0 on default port 8032] org.apache.hadoop.yarn.server.resourcemanager.scheduler.capacity.CapacityScheduler: Priority '0' is acceptable in queue : default for application: application_1742905687277_0001
2025-03-25 12:28:54,432 WARN [IPC Server handler 0 on default port 8032] org.apache.hadoop.yarn.server.resourcemanager.rmapp.RMAppImpl: The specific max attempts: 0 for application: 1 is invalid, because it is less than or equal to zero. Use the rm max attempts instead.
2025-03-25 12:28:54,433 INFO [RM Event dispatcher] org.apache.hadoop.yarn.server.resourcemanager.rmapp.RMAppImpl: Storing application with id application_1742905687277_0001
2025-03-25 12:28:54,439 INFO [RM StateStore dispatcher] org.apache.hadoop.yarn.server.resourcemanager.recovery.RMStateStore: Storing info for app: application_1742905687277_0001
2025-03-25 12:28:54,439 INFO [RM Event dispatcher] org.apache.hadoop.yarn.server.resourcemanager.rmapp.RMAppImpl: application_1742905687277_0001 State change from NEW to NEW_SAVING on event = START
2025-03-25 12:28:54,439 INFO [RM Event dispatcher] org.apache.hadoop.yarn.server.resourcemanager.rmapp.RMAppImpl: application_1742905687277_0001 State change from NEW_SAVING to SUBMITTED on event = APP_NEW_SAVED
2025-03-25 12:28:54,440 INFO [SchedulerEventDispatcher:Event Processor] org.apache.hadoop.yarn.server.resourcemanager.scheduler.capacity.ParentQueue: Application added - appId: application_1742905687277_0001 user: root leaf-queue of parent: root #applications: 1
2025-03-25 12:28:54,441 INFO [SchedulerEventDispatcher:Event Processor] org.apache.hadoop.yarn.server.resourcemanager.scheduler.capacity.CapacityScheduler: Accepted application application_1742905687277_0001 from user: root, in queue: default
2025-03-25 12:28:54,448 INFO [IPC Server handler 0 on default port 8032] org.apache.hadoop.yarn.server.resourcemanager.ClientRMService: Application with id 1 submitted by user root
2025-03-25 12:28:54,450 INFO [RM Event dispatcher] org.apache.hadoop.yarn.server.resourcemanager.rmapp.RMAppImpl: application_1742905687277_0001 State change from SUBMITTED to ACCEPTED on event = APP_ACCEPTED
2025-03-25 12:28:54,498 INFO [RM Event dispatcher] org.apache.hadoop.yarn.server.resourcemanager.ApplicationMasterService: Registering app attempt : appattempt_1742905687277_0001_000001
2025-03-25 12:28:54,499 INFO [RM Event dispatcher] org.apache.hadoop.yarn.server.resourcemanager.rmapp.attempt.RMAppAttemptImpl: appattempt_1742905687277_0001_000001 State change from NEW to SUBMITTED on event = START
2025-03-25 12:28:54,556 WARN [SchedulerEventDispatcher:Event Processor] org.apache.hadoop.yarn.server.resourcemanager.scheduler.capacity.LeafQueue: maximum-am-resource-percent is insufficient to start a single application in queue, it is likely set too low. skipping enforcement to allow at least one application to start
2025-03-25 12:28:54,556 WARN [SchedulerEventDispatcher:Event Processor] org.apache.hadoop.yarn.server.resourcemanager.scheduler.capacity.LeafQueue: maximum-am-resource-percent is insufficient to start a single application in queue for user, it is likely set too low. skipping enforcement to allow at least one application to start
2025-03-25 12:28:54,557 INFO [SchedulerEventDispatcher:Event Processor] org.apache.hadoop.yarn.server.resourcemanager.scheduler.capacity.LeafQueue: Application application_1742905687277_0001 from user: root activated in queue: root.default
2025-03-25 12:28:54,557 INFO [SchedulerEventDispatcher:Event Processor] org.apache.hadoop.yarn.server.resourcemanager.scheduler.capacity.LeafQueue: Application added - appId: application_1742905687277_0001 user: root, leaf-queue: root.default #user-pending-applications: 0 #user-active-applications: 1 #queue-pending-applications: 0 #queue-active-applications: 1 #queue-nonrunnable-applications: 0
2025-03-25 12:28:54,557 INFO [SchedulerEventDispatcher:Event Processor] org.apache.hadoop.yarn.server.resourcemanager.scheduler.capacity.CapacityScheduler: Added Application Attempt appattempt_1742905687277_0001_000001 to scheduler from user root in queue root.default
2025-03-25 12:28:54,563 INFO [RM Event dispatcher] org.apache.hadoop.yarn.server.resourcemanager.rmapp.attempt.RMAppAttemptImpl: appattempt_1742905687277_0001_000001 State change from SUBMITTED to SCHEDULED on event = ATTEMPT_ADDED
2025-03-25 12:28:54,575 INFO [SchedulerEventDispatcher:Event Processor] org.apache.hadoop.yarn.server.resourcemanager.scheduler.capacity.allocator.AbstractContainerAllocator: assignedContainer application attempt=appattempt_1742905687277_0001_000001 container=null queue=default clusterResource=<memory:24576, vCores:24> type=OFF_SWITCH requestedPartition=
2025-03-25 12:28:54,576 INFO [SchedulerEventDispatcher:Event Processor] org.apache.hadoop.yarn.server.resourcemanager.rmcontainer.RMContainerImpl: container_1742905687277_0001_01_000001 Container Transitioned from NEW to ALLOCATED
2025-03-25 12:28:54,577 INFO [SchedulerEventDispatcher:Event Processor] org.apache.hadoop.yarn.server.resourcemanager.scheduler.common.fica.FiCaSchedulerNode: Assigned container container_1742905687277_0001_01_000001 of capacity <memory:5120, vCores:1> on host slave0:33151, which has 1 containers, <memory:5120, vCores:1> used and <memory:3072, vCores:7> available after allocation
2025-03-25 12:28:54,580 INFO [SchedulerEventDispatcher:Event Processor] org.apache.hadoop.yarn.server.resourcemanager.scheduler.capacity.ParentQueue: assignedContainer queue=root usedCapacity=0.20833333 absoluteUsedCapacity=0.20833333 used=<memory:5120, vCores:1> cluster=<memory:24576, vCores:24>
2025-03-25 12:28:54,580 INFO [SchedulerEventDispatcher:Event Processor] org.apache.hadoop.yarn.server.resourcemanager.scheduler.capacity.CapacityScheduler: Allocation proposal accepted
2025-03-25 12:28:54,588 INFO [RM Event dispatcher] org.apache.hadoop.yarn.server.resourcemanager.rmcontainer.RMContainerImpl: container_1742905687277_0001_01_000001 Container Transitioned from ALLOCATED to ACQUIRED
2025-03-25 12:28:54,588 INFO [RM Event dispatcher] org.apache.hadoop.yarn.server.resourcemanager.security.NMTokenSecretManagerInRM: Clear node set for appattempt_1742905687277_0001_000001
2025-03-25 12:28:54,588 INFO [RM Event dispatcher] org.apache.hadoop.yarn.server.resourcemanager.rmapp.attempt.RMAppAttemptImpl: Storing attempt: AppId: application_1742905687277_0001 AttemptId: appattempt_1742905687277_0001_000001 MasterContainer: Container: [ContainerId: container_1742905687277_0001_01_000001, AllocationRequestId: -1, Version: 0, NodeId: slave0:33151, NodeHttpAddress: slave0:8042, Resource: <memory:5120, vCores:1>, Priority: 0, Token: Token { kind: ContainerToken, service: 172.20.1.15:33151 }, ExecutionType: GUARANTEED, ]
2025-03-25 12:28:54,593 INFO [RM Event dispatcher] org.apache.hadoop.yarn.server.resourcemanager.rmapp.attempt.RMAppAttemptImpl: appattempt_1742905687277_0001_000001 State change from SCHEDULED to ALLOCATED_SAVING on event = CONTAINER_ALLOCATED
2025-03-25 12:28:54,595 INFO [RM Event dispatcher] org.apache.hadoop.yarn.server.resourcemanager.rmapp.attempt.RMAppAttemptImpl: appattempt_1742905687277_0001_000001 State change from ALLOCATED_SAVING to ALLOCATED on event = ATTEMPT_NEW_SAVED
2025-03-25 12:28:54,612 INFO [ApplicationMasterLauncher #0] org.apache.hadoop.yarn.server.resourcemanager.amlauncher.AMLauncher: Launching masterappattempt_1742905687277_0001_000001
2025-03-25 12:28:54,646 INFO [ApplicationMasterLauncher #0] org.apache.hadoop.yarn.server.resourcemanager.amlauncher.AMLauncher: Setting up container Container: [ContainerId: container_1742905687277_0001_01_000001, AllocationRequestId: -1, Version: 0, NodeId: slave0:33151, NodeHttpAddress: slave0:8042, Resource: <memory:5120, vCores:1>, Priority: 0, Token: Token { kind: ContainerToken, service: 172.20.1.15:33151 }, ExecutionType: GUARANTEED, ] for AM appattempt_1742905687277_0001_000001
2025-03-25 12:28:54,646 INFO [ApplicationMasterLauncher #0] org.apache.hadoop.yarn.server.resourcemanager.security.AMRMTokenSecretManager: Create AMRMToken for ApplicationAttempt: appattempt_1742905687277_0001_000001
2025-03-25 12:28:54,648 INFO [ApplicationMasterLauncher #0] org.apache.hadoop.yarn.server.resourcemanager.security.AMRMTokenSecretManager: Creating password for appattempt_1742905687277_0001_000001
2025-03-25 12:28:54,798 INFO [ApplicationMasterLauncher #0] org.apache.hadoop.yarn.server.resourcemanager.amlauncher.AMLauncher: Done launching container Container: [ContainerId: container_1742905687277_0001_01_000001, AllocationRequestId: -1, Version: 0, NodeId: slave0:33151, NodeHttpAddress: slave0:8042, Resource: <memory:5120, vCores:1>, Priority: 0, Token: Token { kind: ContainerToken, service: 172.20.1.15:33151 }, ExecutionType: GUARANTEED, ] for AM appattempt_1742905687277_0001_000001
2025-03-25 12:28:54,798 INFO [RM Event dispatcher] org.apache.hadoop.yarn.server.resourcemanager.rmapp.attempt.RMAppAttemptImpl: appattempt_1742905687277_0001_000001 State change from ALLOCATED to LAUNCHED on event = LAUNCHED
2025-03-25 12:28:54,798 INFO [RM Event dispatcher] org.apache.hadoop.yarn.server.resourcemanager.rmapp.RMAppImpl: update the launch time for applicationId: application_1742905687277_0001, attemptId: appattempt_1742905687277_0001_000001launchTime: 1742905734798
2025-03-25 12:28:54,799 INFO [RM StateStore dispatcher] org.apache.hadoop.yarn.server.resourcemanager.recovery.RMStateStore: Updating info for app: application_1742905687277_0001
2025-03-25 12:28:55,504 INFO [SchedulerEventDispatcher:Event Processor] org.apache.hadoop.yarn.server.resourcemanager.rmcontainer.RMContainerImpl: container_1742905687277_0001_01_000001 Container Transitioned from ACQUIRED to RUNNING
2025-03-25 12:28:58,735 INFO [Socket Reader #1 for port 8030] SecurityLogger.org.apache.hadoop.ipc.Server: Auth successful for appattempt_1742905687277_0001_000001 (auth:SIMPLE) from 172.20.1.15:42322
2025-03-25 12:28:58,748 INFO [IPC Server handler 3 on default port 8030] org.apache.hadoop.yarn.server.resourcemanager.DefaultAMSProcessor: AM registration appattempt_1742905687277_0001_000001
2025-03-25 12:28:58,749 INFO [RM Event dispatcher] org.apache.hadoop.yarn.server.resourcemanager.rmapp.attempt.RMAppAttemptImpl: appattempt_1742905687277_0001_000001 State change from LAUNCHED to RUNNING on event = REGISTERED
2025-03-25 12:28:58,749 INFO [RM Event dispatcher] org.apache.hadoop.yarn.server.resourcemanager.rmapp.RMAppImpl: application_1742905687277_0001 State change from ACCEPTED to RUNNING on event = ATTEMPT_REGISTERED
2025-03-25 12:28:59,514 INFO [SchedulerEventDispatcher:Event Processor] org.apache.hadoop.yarn.server.resourcemanager.scheduler.capacity.allocator.AbstractContainerAllocator: assignedContainer application attempt=appattempt_1742905687277_0001_000001 container=null queue=default clusterResource=<memory:24576, vCores:24> type=OFF_SWITCH requestedPartition=
2025-03-25 12:28:59,515 INFO [SchedulerEventDispatcher:Event Processor] org.apache.hadoop.yarn.server.resourcemanager.rmcontainer.RMContainerImpl: container_1742905687277_0001_01_000002 Container Transitioned from NEW to ALLOCATED
2025-03-25 12:28:59,515 INFO [SchedulerEventDispatcher:Event Processor] org.apache.hadoop.yarn.server.resourcemanager.scheduler.common.fica.FiCaSchedulerNode: Assigned container container_1742905687277_0001_01_000002 of capacity <memory:3072, vCores:1> on host slave0:33151, which has 2 containers, <memory:8192, vCores:2> used and <memory:0, vCores:6> available after allocation
2025-03-25 12:28:59,515 INFO [SchedulerEventDispatcher:Event Processor] org.apache.hadoop.yarn.server.resourcemanager.scheduler.capacity.ParentQueue: assignedContainer queue=root usedCapacity=0.33333334 absoluteUsedCapacity=0.33333334 used=<memory:8192, vCores:2> cluster=<memory:24576, vCores:24>
2025-03-25 12:28:59,515 INFO [SchedulerEventDispatcher:Event Processor] org.apache.hadoop.yarn.server.resourcemanager.scheduler.capacity.CapacityScheduler: Allocation proposal accepted
2025-03-25 12:28:59,567 INFO [SchedulerEventDispatcher:Event Processor] org.apache.hadoop.yarn.server.resourcemanager.scheduler.capacity.allocator.AbstractContainerAllocator: assignedContainer application attempt=appattempt_1742905687277_0001_000001 container=null queue=default clusterResource=<memory:24576, vCores:24> type=OFF_SWITCH requestedPartition=
2025-03-25 12:28:59,568 INFO [SchedulerEventDispatcher:Event Processor] org.apache.hadoop.yarn.server.resourcemanager.rmcontainer.RMContainerImpl: container_1742905687277_0001_01_000003 Container Transitioned from NEW to ALLOCATED
2025-03-25 12:28:59,569 INFO [SchedulerEventDispatcher:Event Processor] org.apache.hadoop.yarn.server.resourcemanager.scheduler.common.fica.FiCaSchedulerNode: Assigned container container_1742905687277_0001_01_000003 of capacity <memory:3072, vCores:1> on host slave1:37953, which has 1 containers, <memory:3072, vCores:1> used and <memory:5120, vCores:7> available after allocation
2025-03-25 12:28:59,569 INFO [SchedulerEventDispatcher:Event Processor] org.apache.hadoop.yarn.server.resourcemanager.scheduler.capacity.ParentQueue: assignedContainer queue=root usedCapacity=0.45833334 absoluteUsedCapacity=0.45833334 used=<memory:11264, vCores:3> cluster=<memory:24576, vCores:24>
2025-03-25 12:28:59,569 INFO [SchedulerEventDispatcher:Event Processor] org.apache.hadoop.yarn.server.resourcemanager.scheduler.capacity.CapacityScheduler: Allocation proposal accepted
2025-03-25 12:28:59,650 INFO [SchedulerEventDispatcher:Event Processor] org.apache.hadoop.yarn.server.resourcemanager.scheduler.capacity.allocator.AbstractContainerAllocator: assignedContainer application attempt=appattempt_1742905687277_0001_000001 container=null queue=default clusterResource=<memory:24576, vCores:24> type=OFF_SWITCH requestedPartition=
2025-03-25 12:28:59,651 INFO [SchedulerEventDispatcher:Event Processor] org.apache.hadoop.yarn.server.resourcemanager.rmcontainer.RMContainerImpl: container_1742905687277_0001_01_000004 Container Transitioned from NEW to ALLOCATED
2025-03-25 12:28:59,651 INFO [SchedulerEventDispatcher:Event Processor] org.apache.hadoop.yarn.server.resourcemanager.scheduler.common.fica.FiCaSchedulerNode: Assigned container container_1742905687277_0001_01_000004 of capacity <memory:3072, vCores:1> on host slave2:46613, which has 1 containers, <memory:3072, vCores:1> used and <memory:5120, vCores:7> available after allocation
2025-03-25 12:28:59,651 INFO [SchedulerEventDispatcher:Event Processor] org.apache.hadoop.yarn.server.resourcemanager.scheduler.capacity.ParentQueue: assignedContainer queue=root usedCapacity=0.5833333 absoluteUsedCapacity=0.5833333 used=<memory:14336, vCores:4> cluster=<memory:24576, vCores:24>
2025-03-25 12:28:59,651 INFO [SchedulerEventDispatcher:Event Processor] org.apache.hadoop.yarn.server.resourcemanager.scheduler.capacity.CapacityScheduler: Allocation proposal accepted
2025-03-25 12:28:59,869 INFO [IPC Server handler 2 on default port 8030] org.apache.hadoop.yarn.server.resourcemanager.rmcontainer.RMContainerImpl: container_1742905687277_0001_01_000002 Container Transitioned from ALLOCATED to ACQUIRED
2025-03-25 12:28:59,870 INFO [IPC Server handler 2 on default port 8030] org.apache.hadoop.yarn.server.resourcemanager.rmcontainer.RMContainerImpl: container_1742905687277_0001_01_000003 Container Transitioned from ALLOCATED to ACQUIRED
2025-03-25 12:28:59,870 INFO [IPC Server handler 2 on default port 8030] org.apache.hadoop.yarn.server.resourcemanager.rmcontainer.RMContainerImpl: container_1742905687277_0001_01_000004 Container Transitioned from ALLOCATED to ACQUIRED
2025-03-25 12:29:00,517 INFO [SchedulerEventDispatcher:Event Processor] org.apache.hadoop.yarn.server.resourcemanager.rmcontainer.RMContainerImpl: container_1742905687277_0001_01_000002 Container Transitioned from ACQUIRED to RUNNING
2025-03-25 12:29:00,575 INFO [SchedulerEventDispatcher:Event Processor] org.apache.hadoop.yarn.server.resourcemanager.rmcontainer.RMContainerImpl: container_1742905687277_0001_01_000003 Container Transitioned from ACQUIRED to RUNNING
2025-03-25 12:29:00,661 INFO [SchedulerEventDispatcher:Event Processor] org.apache.hadoop.yarn.server.resourcemanager.rmcontainer.RMContainerImpl: container_1742905687277_0001_01_000004 Container Transitioned from ACQUIRED to RUNNING
2025-03-25 12:29:02,912 INFO [IPC Server handler 5 on default port 8030] org.apache.hadoop.yarn.server.resourcemanager.scheduler.AppSchedulingInfo: checking for deactivate of application :application_1742905687277_0001
2025-03-25 12:29:11,358 INFO [SchedulerEventDispatcher:Event Processor] org.apache.hadoop.yarn.server.resourcemanager.rmcontainer.RMContainerImpl: container_1742905687277_0001_01_000003 Container Transitioned from RUNNING to COMPLETED
2025-03-25 12:29:11,383 INFO [SchedulerEventDispatcher:Event Processor] org.apache.hadoop.yarn.server.resourcemanager.rmcontainer.RMContainerImpl: container_1742905687277_0001_01_000004 Container Transitioned from RUNNING to COMPLETED
2025-03-25 12:29:11,397 INFO [SchedulerEventDispatcher:Event Processor] org.apache.hadoop.yarn.server.resourcemanager.rmcontainer.RMContainerImpl: container_1742905687277_0001_01_000002 Container Transitioned from RUNNING to COMPLETED
2025-03-25 12:29:11,403 INFO [RM Event dispatcher] org.apache.hadoop.yarn.server.resourcemanager.rmapp.attempt.RMAppAttemptImpl: Updating application attempt appattempt_1742905687277_0001_000001 with final state: FINISHING, and exit status: -1000
2025-03-25 12:29:11,403 INFO [RM Event dispatcher] org.apache.hadoop.yarn.server.resourcemanager.rmapp.attempt.RMAppAttemptImpl: appattempt_1742905687277_0001_000001 State change from RUNNING to FINAL_SAVING on event = UNREGISTERED
2025-03-25 12:29:11,403 INFO [RM Event dispatcher] org.apache.hadoop.yarn.server.resourcemanager.rmapp.RMAppImpl: Updating application application_1742905687277_0001 with final state: FINISHING
2025-03-25 12:29:11,404 INFO [RM StateStore dispatcher] org.apache.hadoop.yarn.server.resourcemanager.recovery.RMStateStore: Updating info for app: application_1742905687277_0001
2025-03-25 12:29:11,404 INFO [RM Event dispatcher] org.apache.hadoop.yarn.server.resourcemanager.rmapp.RMAppImpl: application_1742905687277_0001 State change from RUNNING to FINAL_SAVING on event = ATTEMPT_UNREGISTERED
2025-03-25 12:29:11,404 INFO [RM Event dispatcher] org.apache.hadoop.yarn.server.resourcemanager.rmapp.attempt.RMAppAttemptImpl: appattempt_1742905687277_0001_000001 State change from FINAL_SAVING to FINISHING on event = ATTEMPT_UPDATE_SAVED
2025-03-25 12:29:11,405 INFO [RM Event dispatcher] org.apache.hadoop.yarn.server.resourcemanager.rmapp.RMAppImpl: application_1742905687277_0001 State change from FINAL_SAVING to FINISHING on event = APP_UPDATE_SAVED
2025-03-25 12:29:11,505 INFO [IPC Server handler 2 on default port 8030] org.apache.hadoop.yarn.server.resourcemanager.ApplicationMasterService: application_1742905687277_0001 unregistered successfully. 
2025-03-25 12:29:11,642 INFO [SchedulerEventDispatcher:Event Processor] org.apache.hadoop.yarn.server.resourcemanager.rmcontainer.RMContainerImpl: container_1742905687277_0001_01_000001 Container Transitioned from RUNNING to COMPLETED
2025-03-25 12:29:11,643 INFO [RM Event dispatcher] org.apache.hadoop.yarn.server.resourcemanager.ApplicationMasterService: Unregistering app attempt : appattempt_1742905687277_0001_000001
2025-03-25 12:29:11,644 INFO [RM Event dispatcher] org.apache.hadoop.yarn.server.resourcemanager.security.AMRMTokenSecretManager: Application finished, removing password for appattempt_1742905687277_0001_000001
2025-03-25 12:29:11,645 INFO [RM Event dispatcher] org.apache.hadoop.yarn.server.resourcemanager.rmapp.attempt.RMAppAttemptImpl: appattempt_1742905687277_0001_000001 State change from FINISHING to FINISHED on event = CONTAINER_FINISHED
2025-03-25 12:29:11,647 INFO [RM Event dispatcher] org.apache.hadoop.yarn.server.resourcemanager.rmapp.RMAppImpl: application_1742905687277_0001 State change from FINISHING to FINISHED on event = ATTEMPT_FINISHED
2025-03-25 12:29:11,647 INFO [SchedulerEventDispatcher:Event Processor] org.apache.hadoop.yarn.server.resourcemanager.scheduler.capacity.CapacityScheduler: Application Attempt appattempt_1742905687277_0001_000001 is done. finalState=FINISHED
2025-03-25 12:29:11,648 INFO [SchedulerEventDispatcher:Event Processor] org.apache.hadoop.yarn.server.resourcemanager.scheduler.AppSchedulingInfo: Application application_1742905687277_0001 requests cleared
2025-03-25 12:29:11,648 INFO [SchedulerEventDispatcher:Event Processor] org.apache.hadoop.yarn.server.resourcemanager.scheduler.capacity.LeafQueue: Application removed - appId: application_1742905687277_0001 user: root queue: root.default #user-pending-applications: 0 #user-active-applications: 0 #queue-pending-applications: 0 #queue-active-applications: 0
2025-03-25 12:29:11,649 INFO [SchedulerEventDispatcher:Event Processor] org.apache.hadoop.yarn.server.resourcemanager.scheduler.capacity.ParentQueue: Application removed - appId: application_1742905687277_0001 user: root leaf-queue of parent: root #applications: 0
2025-03-25 12:29:11,649 INFO [ApplicationMasterLauncher #1] org.apache.hadoop.yarn.server.resourcemanager.amlauncher.AMLauncher: Cleaning master appattempt_1742905687277_0001_000001
2025-03-25 12:29:11,653 INFO [RM Event dispatcher] org.apache.hadoop.yarn.server.resourcemanager.RMAppManager$ApplicationSummary: appId=application_1742905687277_0001,name=org.apache.spark.examples.ml.DeveloperApiExample,user=root,queue=default,state=FINISHED,trackingUrl=http://master:8088/proxy/application_1742905687277_0001/,appMasterHost=slave0,submitTime=1742905734359,startTime=1742905734432,launchTime=1742905734798,finishTime=1742905751403,finalStatus=SUCCEEDED,memorySeconds=196156,vcoreSeconds=50,preemptedMemorySeconds=0,preemptedVcoreSeconds=0,preemptedAMContainers=0,preemptedNonAMContainers=0,preemptedResources=<memory:0\, vCores:0>,applicationType=SPARK,resourceSeconds=196156 MB-seconds\, 50 vcore-seconds,preemptedResourceSeconds=0 MB-seconds\, 0 vcore-seconds,applicationTags=,applicationNodeLabel=,diagnostics=,totalAllocatedContainers=4
